Workbook
Name SKD440型库存明细: 空白表格!$A$1:$I$1
Name SKD440型库存明细: 'SKD440 型'!$A$1:$I$1
Name SKD440型库存明细: 其它型号!$A$1:$I$1
Name SKD440型库存明细: '插销销子-钢丝'!$A$1:$I$1
Name SKD440型库存明细: '空白表格 (2)'!$A$1:$I$1
Name SKD440型库存明细: '201-45#发黑系列'!$A$1:$I$1
Name SKD440型库存明细: 密实螺套型!$A$1:$I$1

Sheet 总汇
A1: 三诚-分类汇总明细 | I1: 备货成本统计
A2: 类别 | B2: 本月入库总汇 | C2: 本月出库总汇 | D2: 上月库存 | E2: 现库存 | F2: 增浮率
A3: 常规 | I3: 302槽型
A4: 特殊常规-薄壁型 | I4: 307孔型
A5: 内外牙 | I5: 308孔型
A6: 内外牙一字槽 | I6: 带帽子型
A7: 非标槽型 | I7: 盲孔型
A8: 非标孔型 | I8: 303薄壁型
A9: 螺母-H-E型 | I9: 201型有槽
A10: 特殊非标 | I10: 200型无槽
A11: 特殊材质 | I11: 插销螺套
A12: 安装工具
A13: 插销螺套
A14: 插销胚料 | I14: 合计：
A15: 汇总：
J21: =SUM(J3:J20) -> 0

Sheet 302槽型
A1: 302槽型自攻螺套库存明细
A2: 日期 | B2: 46023 | D2: 本月入库统计 | H2: 每日入库统计
D3: 本月出库统计 | H3: 每日出库统计
A4: 序号 | B4: 类别 | C4: 规格 | D4: 材质 | E4: 上月结存 | F4: 单位 | G4: 现库存 | H4: 入/出库 | I4: 汇总 | J4: 46023 | K4: 46024 | L4: 46025 | M4: 46026 | N4: 46027 | O4: 46028 | P4: 46029 | Q4: 46030 | R4: 46031 | S4: 46032 | T4: 46033 | U4: 46034 | V4: 46035 | W4: 46036 | X4: 46037 | Y4: 46038 | Z4: 46039 | AA4: 46040 | AB4: 46041 | AC4: 46042 | AD4: 46043 | AE4: 46044 | AF4: 46045 | AG4: 46046 | AH4: 46047 | AI4: 46048 | AJ4: 46049 | AK4: 46050 | AL4: 46051 | AM4: 46052 | AN4: 46053 | AO4: 46054
A5: 1 | B5: 302槽型 | C5: M2*0.4-L6-M4.5*0.5 | D5: SUS303 | E5: 4937 | F5: pcs | G5: =E5+I5-I6 -> 4937 | H5: 入库 | I5: =SUM(J5:AO5) -> 0
H6: 出库 | I6: =SUM(J6:AO6) -> 0
A7: 2 | B7: 302槽型 | C7: M2*0.4-L6-M4.5*0.5 | D7: 1215黄锌 | E7: 11 | F7: pcs | G7: =E7+I7-I8 -> 11 | H7: 入库 | I7: =SUM(J7:AO7) -> 0
H8: 出库 | I8: =SUM(J8:AO8) -> 0
A9: 3 | B9: 非标槽型 | C9: M2*0.4-L4-M4.5*0.5 | D9: SUS303 | E9: 2150 | F9: pcs | G9: =E9+I9-I10 -> 2150 | H9: 入库 | I9: =SUM(J9:AO9) -> 0
H10: 出库 | I10: =SUM(J10:AO10) -> 0
A11: 4 | B11: 302槽型 | C11: M2.5*0.45-L6-M4.5*0.5 | D11: SUS303 | E11: 29741 | F11: pcs | G11: =E11+I11-I12 -> 29741 | H11: 入库 | I11: =SUM(J11:AO11) -> 0
H12: 出库 | I12: =SUM(J12:AO12) -> 0
A13: 5 | B13: 302槽型 | C13: M2.5*0.45-L6-M4.5*0.5 | D13: 1215黄锌 | E13: 3506 | F13: pcs | G13: =E13+I13-I14 -> 3506 | H13: 入库 | I13: =SUM(J13:AO13) -> 0
H14: 出库 | I14: =SUM(J14:AO14) -> 0
A15: 6 | B15: 302槽型 | C15: M2.5*0.45-L6-M4.5*0.5 | D15: 1215彩锌 | E15: 4000 | F15: pcs | G15: =E15+I15-I16 -> 4000 | H15: 入库 | I15: =SUM(J15:AO15) -> 0
H16: 出库 | I16: =SUM(J16:AO16) -> 0
A17: 7 | B17: 302槽型 | C17: M3*0.5-L6-M5*0.5 | D17: SUS303 | E17: 9285 | F17: pcs | G17: =E17+I17-I18 -> 15235 | H17: 入库 | I17: =SUM(J17:AO17) -> 20000 | AD17: 20000
H18: 出库 | I18: =SUM(J18:AO18) -> 14050 | Q18: 4000 | X18: 1050 | AE18: 9000
A19: 8 | B19: 302槽型 | C19: M3*0.5-L6-M5*0.5 | D19: 1215黄锌 | E19: 3315 | F19: pcs | G19: =E19+I19-I20 -> 3315 | H19: 入库 | I19: =SUM(J19:AO19) -> 0
H20: 出库 | I20: =SUM(J20:AO20) -> 0
A21: 9 | B21: 302槽型 | C21: M3*0.5-L6-M5*0.5 | D21: 1215蓝锌 | E21: 2270 | F21: pcs | G21: =E21+I21-I22 -> 2270 | H21: 入库 | I21: =SUM(J21:AO21) -> 0
H22: 出库 | I22: =SUM(J22:AO22) -> 0
A23: 10 | B23: 302槽型 | C23: M3*0.5-L6-M5*0.5 | D23: 1215彩锌 | E23: 5000 | F23: pcs | G23: =E23+I23-I24 -> 5000 | H23: 入库 | I23: =SUM(J23:AO23) -> 0
H24: 出库 | I24: =SUM(J24:AO24) -> 0
A25: 11 | B25: 非标槽型 | C25: M3*0.5-L7.5-M6.5*0.75 | D25: C3604 | E25: 340 | F25: pcs | G25: =E25+I25-I26 -> 340 | H25: 入库 | I25: =SUM(J25:AO25) -> 0
H26: 出库 | I26: =SUM(J26:AO26) -> 0
A27: 13 | B27: 非标槽型 | C27: M3*0.5-L3-M5*0.5 | D27: 304F | E27: 0 | F27: pcs | G27: =E27+I27-I28 -> 330 | H27: 入库 | I27: =SUM(J27:AO27) -> 5330 | K27: =4600+730 -> 5330
H28: 出库 | I28: =SUM(J28:AO28) -> 5000 | K28: 5000
A29: 13 | B29: 非标槽型 | C29: M3*0.5-L3.5-M5*0.5 | D29: SUS303 | E29: 2225 | F29: pcs | G29: =E29+I29-I30 -> 2225 | H29: 入库 | I29: =SUM(J29:AO29) -> 0
H30: 出库 | I30: =SUM(J30:AO30) -> 0
A31: 12 | B31: 非标槽型 | C31: M3*0.5-L4-M5*0.5 | D31: SUS303 | E31: 29675 | F31: pcs | G31: =E31+I31-I32 -> 29675 | H31: 入库 | I31: =SUM(J31:AO31) -> 0
H32: 出库 | I32: =SUM(J32:AO32) -> 0
A33: 13 | B33: 非标槽型 | C33: M3*0.5-L5-M5*0.5 | D33: SUS303 | E33: 0 | F33: pcs | G33: =E33+I33-I34 -> 0 | H33: 入库 | I33: =SUM(J33:AO33) -> 0
H34: 出库 | I34: =SUM(J34:AO34) -> 0
A35: 14 | B35: 非标槽型 | C35: M3*0.5-L8-M5*0.5 | D35: SUS303 | E35: 13680 | F35: pcs | G35: =E35+I35-I36 -> 13680 | H35: 入库 | I35: =SUM(J35:AO35) -> 0
H36: 出库 | I36: =SUM(J36:AO36) -> 0
A37: 15 | B37: 非标槽型 | C37: M3*0.5-L10-M5*0.5 | D37: SUS303 | E37: 1266 | F37: pcs | G37: =E37+I37-I38 -> 1266 | H37: 入库 | I37: =SUM(J37:AO37) -> 0
H38: 出库 | I38: =SUM(J38:AO38) -> 0
A39: 15 | B39: 非标槽型 | C39: M3*0.5-L12-M5*0.5 | D39: SUS303 | E39: 0 | F39: pcs | G39: =E39+I39-I40 -> 480 | H39: 入库 | I39: =SUM(J39:AO39) -> 1480 | O39: 1480
H40: 出库 | I40: =SUM(J40:AO40) -> 1000 | O40: 1000
...

Sheet 307孔型 短
A1: 307孔型自攻螺套库存明细
A2: 日期 | B2: ='302槽型'!B2 -> 46023 | D2: 本月入库统计 | H2: 每日入库统计 | J2: =SUMIF($H:$H,#REF!,J:J) -> 0 | K2: =SUMIF($H:$H,#REF!,K:K) -> 0 | L2: =SUMIF($H:$H,#REF!,L:L) -> 0 | M2: =SUMIF($H:$H,#REF!,M:M) -> 0 | N2: =SUMIF($H:$H,#REF!,N:N) -> 0 | O2: =SUMIF($H:$H,#REF!,O:O) -> 0 | P2: =SUMIF($H:$H,#REF!,P:P) -> 0 | Q2: =SUMIF($H:$H,#REF!,Q:Q) -> 0 | R2: =SUMIF($H:$H,#REF!,R:R) -> 0 | S2: =SUMIF($H:$H,#REF!,S:S) -> 0 | T2: =SUMIF($H:$H,#REF!,T:T) -> 0 | U2: =SUMIF($H:$H,#REF!,U:U) -> 0 | V2: =SUMIF($H:$H,#REF!,V:V) -> 0 | W2: =SUMIF($H:$H,#REF!,W:W) -> 0 | X2: =SUMIF($H:$H,#REF!,X:X) -> 0 | Y2: =SUMIF($H:$H,#REF!,Y:Y) -> 0 | Z2: =SUMIF($H:$H,#REF!,Z:Z) -> 0 | AA2: =SUMIF($H:$H,#REF!,AA:AA) -> 0 | AB2: =SUMIF($H:$H,#REF!,AB:AB) -> 0 | AC2: =SUMIF($H:$H,#REF!,AC:AC) -> 0 | AD2: =SUMIF($H:$H,#REF!,AD:AD) -> 0 | AE2: =SUMIF($H:$H,#REF!,AE:AE) -> 0 | AF2: =SUMIF($H:$H,#REF!,AF:AF) -> 0 | AG2: =SUMIF($H:$H,#REF!,AG:AG) -> 0 | AH2: =SUMIF($H:$H,#REF!,AH:AH) -> 0 | AI2: =SUMIF($H:$H,#REF!,AI:AI) -> 0 | AJ2: =SUMIF($H:$H,#REF!,AJ:AJ) -> 0 | AK2: =SUMIF($H:$H,#REF!,AK:AK) -> 0 | AL2: =SUMIF($H:$H,#REF!,AL:AL) -> 0 | AM2: =SUMIF($H:$H,#REF!,AM:AM) -> 0 | AN2: =SUMIF($H:$H,#REF!,AN:AN) -> 0
D3: 本月出库统计 | H3: 每日出库统计 | J3: =SUMIF($H:$H,#REF!,J:J) -> 0 | K3: =SUMIF($H:$H,#REF!,K:K) -> 0 | L3: =SUMIF($H:$H,#REF!,L:L) -> 0 | M3: =SUMIF($H:$H,#REF!,M:M) -> 0 | N3: =SUMIF($H:$H,#REF!,N:N) -> 0 | O3: =SUMIF($H:$H,#REF!,O:O) -> 0 | P3: =SUMIF($H:$H,#REF!,P:P) -> 0 | Q3: =SUMIF($H:$H,#REF!,Q:Q) -> 0 | R3: =SUMIF($H:$H,#REF!,R:R) -> 0 | S3: =SUMIF($H:$H,#REF!,S:S) -> 0 | T3: =SUMIF($H:$H,#REF!,T:T) -> 0 | U3: =SUMIF($H:$H,#REF!,U:U) -> 0 | V3: =SUMIF($H:$H,#REF!,V:V) -> 0 | W3: =SUMIF($H:$H,#REF!,W:W) -> 0 | X3: =SUMIF($H:$H,#REF!,X:X) -> 0 | Y3: =SUMIF($H:$H,#REF!,Y:Y) -> 0 | Z3: =SUMIF($H:$H,#REF!,Z:Z) -> 0 | AA3: =SUMIF($H:$H,#REF!,AA:AA) -> 0 | AB3: =SUMIF($H:$H,#REF!,AB:AB) -> 0 | AC3: =SUMIF($H:$H,#REF!,AC:AC) -> 0 | AD3: =SUMIF($H:$H,#REF!,AD:AD) -> 0 | AE3: =SUMIF($H:$H,#REF!,AE:AE) -> 0 | AF3: =SUMIF($H:$H,#REF!,AF:AF) -> 0 | AG3: =SUMIF($H:$H,#REF!,AG:AG) -> 0 | AH3: =SUMIF($H:$H,#REF!,AH:AH) -> 0 | AI3: =SUMIF($H:$H,#REF!,AI:AI) -> 0 | AJ3: =SUMIF($H:$H,#REF!,AJ:AJ) -> 0 | AK3: =SUMIF($H:$H,#REF!,AK:AK) -> 0 | AL3: =SUMIF($H:$H,#REF!,AL:AL) -> 0 | AM3: =SUMIF($H:$H,#REF!,AM:AM) -> 0 | AN3: =SUMIF($H:$H,#REF!,AN:AN) -> 0
A4: 序号 | B4: 类别 | C4: 规格 | D4: 材质 | E4: 上月结存 | F4: 单位 | G4: 现库存 | H4: 入/出库 | I4: 汇总 | J4: ='302槽型'!J4 -> 46023 | K4: ='302槽型'!K4 -> 46024 | L4: ='302槽型'!L4 -> 46025 | M4: ='302槽型'!M4 -> 46026 | N4: ='302槽型'!N4 -> 46027 | O4: ='302槽型'!O4 -> 46028 | P4: ='302槽型'!P4 -> 46029 | Q4: ='302槽型'!Q4 -> 46030 | ... AN4: ='302槽型'!AN4 -> 46053
A5: 1 | B5: 307孔型 | C5: M2*0.4-L4-M4.5*0.5 | D5: SUS303 | E5: 2107 | F5: pcs | G5: =E5+I5-I6 -> 2107 | H5: 入库 | I5: =SUM(J5:AO5) -> 0
H6: 出库 | I6: =SUM(J6:AO6) -> 0
A7: 2 | B7: 307孔型 | C7: M2*0.4-L4-M4.5*0.5 | D7: 1215 蓝锌 | E7: 2376 | F7: pcs | G7: =E7+I7-I8 -> 2376 | H7: 入库 | I7: =SUM(J7:AO7) -> 0
H8: 出库 | I8: =SUM(J8:AO8) -> 0
A9: 3 | B9: 307孔型 | C9: M2.5*0.45-L4-M4.5*0.5 | D9: SUS303 | E9: 2390 | F9: pcs | G9: =E9+I9-I10 -> 2390 | H9: 入库 | I9: =SUM(J9:AO9) -> 0
H10: 出库 | I10: =SUM(J10:AO10) -> 0
A11: 4 | B11: 307孔型 | C11: M2.5*0.45-L4-M4.5*0.5 | D11: 1215 蓝锌 | E11: 2850 | F11: pcs | G11: =E11+I11-I12 -> 2850 | H11: 入库 | I11: =SUM(J11:AO11) -> 0
H12: 出库 | I12: =SUM(J12:AO12) -> 0
A13: 5 | B13: 307孔型 | C13: M3*0.5-L4-M5*0.6 | D13: SUS303 | E13: 75137 | F13: pcs | G13: =E13+I13-I14 -> 72967 | H13: 入库 | I13: =SUM(J13:AO13) -> 0
H14: 出库 | I14: =SUM(J14:AO14) -> 2170 | S14: 20 | V14: 350 | Y14: =300+1000 -> 1300 | AB14: 500
A15: 6 | B15: 307孔型 | C15: M3*0.5-L4-M5*0.6 | D15: 1215 黄锌 | E15: 60966 | F15: pcs | G15: =E15+I15-I16 -> 60966 | H15: 入库 | I15: =SUM(J15:AO15) -> 0
H16: 出库 | I16: =SUM(J16:AO16) -> 0
A17: 7 | B17: 307孔型 | C17: M3*0.5-L4-M5*0.6 | D17: 1215 蓝锌 | E17: 200 | F17: pcs | G17: =E17+I17-I18 -> 200 | H17: 入库 | I17: =SUM(J17:AO17) -> 0
H18: 出库 | I18: =SUM(J18:AO18) -> 0
A19: 8 | B19: 307孔型 | C19: M4*0.7-L6-M6.5*0.8 | D19: SUS303 | E19: 34340 | F19: pcs | G19: =E19+I19-I20 -> 30820 | H19: 入库 | I19: =SUM(J19:AO19) -> 0
H20: 出库 | I20: =SUM(J20:AO20) -> 3520 | V20: 20 | Y20: =400+1000 -> 1400 | Z20: 1100 | AB20: 1000
A21: 9 | B21: 307孔型 | C21: M4*0.7-L6-M6.5*0.8 | D21: 1215 蓝锌 | E21: 135 | F21: pcs | G21: =E21+I21-I22 -> 135 | H21: 入库 | I21: =SUM(J21:AO21) -> 0
H22: 出库 | I22: =SUM(J22:AO22) -> 0
A23: 10 | B23: 3072型 | C23: M4*0.7-L6-M6.5*0.8(内六角) | D23: SUS303 | E23: 1075 | F23: pcs | G23: =E23+I23-I24 -> 1075 | H23: 入库 | I23: =SUM(J23:AO23) -> 0
H24: 出库 | I24: =SUM(J24:AO24) -> 0
A25: 11 | B25: 3072型 | C25: M4*0.7-L6-M6.5*0.8(内六角) | D25: 1215 蓝锌 | E25: 10 | F25: pcs | G25: =E25+I25-I26 -> 10 | H25: 入库 | I25: =SUM(J25:AO25) -> 0
H26: 出库 | I26: =SUM(J26:AO26) -> 0
A27: 12 | B27: 307孔型 | C27: M4*0.7-L6-M6.5*0.8 | D27: 1215 黄锌 | E27: 40988 | F27: pcs | G27: =E27+I27-I28 -> 40988 | H27: 入库 | I27: =SUM(J27:AO27) -> 0
H28: 出库 | I28: =SUM(J28:AO28) -> 0
A29: 13 | B29: 307孔型 | C29: M5*0.8-L7-M8*1.0 | D29: SUS303 | E29: 115415 | F29: pcs | G29: =E29+I29-I30 -> 64415 | H29: 入库 | I29: =SUM(J29:AO29) -> 0
H30: 出库 | I30: =SUM(J30:AO30) -> 51000 | Y30: 500 | AB30: 500 | AI30: 50000
A31: 14 | B31: 3072型 | C31: M5*0.8-L7-M8*1.0（内六角） | D31: SUS303 | E31: 1030 | F31: pcs | G31: =E31+I31-I32 -> 1030 | H31: 入库 | I31: =SUM(J31:AO31) -> 0
H32: 出库 | I32: =SUM(J32:AO32) -> 0
A33: 15 | B33: 3072型 | C33: M5*0.8-L7-M8*1.0（内六角） | D33: 1215 蓝锌 | E33: 230 | F33: pcs | G33: =E33+I33-I34 -> 230 | H33: 入库 | I33: =SUM(J33:AO33) -> 0
H34: 出库 | I34: =SUM(J34:AO34) -> 0
A35: 16 | B35: 307孔型 | C35: M5*0.8-L7-M8*1.0 | D35: SUS303(盐雾240H) | E35: 9000 | F35: pcs | G35: =E35+I35-I36 -> 9000 | H35: 入库 | I35: =SUM(J35:AO35) -> 0
H36: 出库 | I36: =SUM(J36:AO36) -> 0
A37: 17 | B37: 307孔型 | C37: M5*0.8-L7-M8*1.0 | D37: 1215 黄锌 | E37: 39376 | F37: pcs | G37: =E37+I37-I38 -> 39376 | H37: 入库 | I37: =SUM(J37:AO37) -> 0
H38: 出库 | I38: =SUM(J38:AO38) -> 0
A39: 18 | B39: 307孔型 | C39: M5*0.8-L7-M8*1.0 | D39: 1215 蓝锌 | E39: 1258 | F39: pcs | G39: =E39+I39-I40 -> 1258 | H39: 入库 | I39: =SUM(J39:AO39) -> 0
H40: 出库 | I40: =SUM(J40:AO40) -> 0
...

Sheet 308孔型 长
A1: 308孔型自攻螺套库存明细
A2: 日期 | B2: ='302槽型'!B2 -> 46023 | D2: 本月入库统计 | H2: 每日入库统计 | J2: =SUMIF($H:$H,#REF!,J:J) -> 0 | K2: =SUMIF($H:$H,#REF!,K:K) -> 0 | L2: =SUMIF($H:$H,#REF!,L:L) -> 0 | M2: =SUMIF($H:$H,#REF!,M:M) -> 0 | N2: =SUMIF($H:$H,#REF!,N:N) -> 0 | O2: =SUMIF($H:$H,#REF!,O:O) -> 0 | P2: =SUMIF($H:$H,#REF!,P:P) -> 0 | Q2: =SUMIF($H:$H,#REF!,Q:Q) -> 0 | R2: =SUMIF($H:$H,#REF!,R:R) -> 0 | S2: =SUMIF($H:$H,#REF!,S:S) -> 0 | T2: =SUMIF($H:$H,#REF!,T:T) -> 0 | U2: =SUMIF($H:$H,#REF!,U:U) -> 0 | V2: =SUMIF($H:$H,#REF!,V:V) -> 0 | W2: =SUMIF($H:$H,#REF!,W:W) -> 0 | X2: =SUMIF($H:$H,#REF!,X:X) -> 0 | Y2: =SUMIF($H:$H,#REF!,Y:Y) -> 0 | Z2: =SUMIF($H:$H,#REF!,Z:Z) -> 0 | AA2: =SUMIF($H:$H,#REF!,AA:AA) -> 0 | AB2: =SUMIF($H:$H,#REF!,AB:AB) -> 0 | AC2: =SUMIF($H:$H,#REF!,AC:AC) -> 0 | AD2: =SUMIF($H:$H,#REF!,AD:AD) -> 0 | AE2: =SUMIF($H:$H,#REF!,AE:AE) -> 0 | AF2: =SUMIF($H:$H,#REF!,AF:AF) -> 0 | AG2: =SUMIF($H:$H,#REF!,AG:AG) -> 0 | AH2: =SUMIF($H:$H,#REF!,AH:AH) -> 0 | AI2: =SUMIF($H:$H,#REF!,AI:AI) -> 0 | AJ2: =SUMIF($H:$H,#REF!,AJ:AJ) -> 0 | AK2: =SUMIF($H:$H,#REF!,AK:AK) -> 0 | AL2: =SUMIF($H:$H,#REF!,AL:AL) -> 0 | AM2: =SUMIF($H:$H,#REF!,AM:AM) -> 0 | AN2: =SUMIF($H:$H,#REF!,AN:AN) -> 0
D3: 本月出库统计 | H3: 每日出库统计 | J3: =SUMIF($H:$H,#REF!,J:J) -> 0 | K3: =SUMIF($H:$H,#REF!,K:K) -> 0 | L3: =SUMIF($H:$H,#REF!,L:L) -> 0 | M3: =SUMIF($H:$H,#REF!,M:M) -> 0 | N3: =SUMIF($H:$H,#REF!,N:N) -> 0 | O3: =SUMIF($H:$H,#REF!,O:O) -> 0 | P3: =SUMIF($H:$H,#REF!,P:P) -> 0 | Q3: =SUMIF($H:$H,#REF!,Q:Q) -> 0 | R3: =SUMIF($H:$H,#REF!,R:R) -> 0 | S3: =SUMIF($H:$H,#REF!,S:S) -> 0 | T3: =SUMIF($H:$H,#REF!,T:T) -> 0 | U3: =SUMIF($H:$H,#REF!,U:U) -> 0 | V3: =SUMIF($H:$H,#REF!,V:V) -> 0 | W3: =SUMIF($H:$H,#REF!,W:W) -> 0 | X3: =SUMIF($H:$H,#REF!,X:X) -> 0 | Y3: =SUMIF($H:$H,#REF!,Y:Y) -> 0 | Z3: =SUMIF($H:$H,#REF!,Z:Z) -> 0 | AA3: =SUMIF($H:$H,#REF!,AA:AA) -> 0 | AB3: =SUMIF($H:$H,#REF!,AB:AB) -> 0 | AC3: =SUMIF($H:$H,#REF!,AC:AC) -> 0 | AD3: =SUMIF($H:$H,#REF!,AD:AD) -> 0 | AE3: =SUMIF($H:$H,#REF!,AE:AE) -> 0 | AF3: =SUMIF($H:$H,#REF!,AF:AF) -> 0 | AG3: =SUMIF($H:$H,#REF!,AG:AG) -> 0 | AH3: =SUMIF($H:$H,#REF!,AH:AH) -> 0 | AI3: =SUMIF($H:$H,#REF!,AI:AI) -> 0 | AJ3: =SUMIF($H:$H,#REF!,AJ:AJ) -> 0 | AK3: =SUMIF($H:$H,#REF!,AK:AK) -> 0 | AL3: =SUMIF($H:$H,#REF!,AL:AL) -> 0 | AM3: =SUMIF($H:$H,#REF!,AM:AM) -> 0 | AN3: =SUMIF($H:$H,#REF!,AN:AN) -> 0
A4: 序号 | B4: 类别 | C4: 规格 | D4: 材质 | E4: 上月结存 | F4: 单位 | G4: 现库存 | H4: 入/出库 | I4: 汇总 | J4: ='302槽型'!J4 -> 46023 | K4: ='302槽型'!K4 -> 46024 | L4: ='302槽型'!L4 -> 46025 | M4: ='302槽型'!M4 -> 46026 | N4: ='302槽型'!N4 -> 46027 | O4: ='302槽型'!O4 -> 46028 | P4: ='302槽型'!P4 -> 46029 | Q4: ='302槽型'!Q4 -> 46030 | ... AN4: ='302槽型'!AN4 -> 46053
A5: 1 | B5: 308孔型 | C5: M3*0.5-L6-M5*0.6 | D5: SUS303 | E5: 87701 | F5: pcs | G5: =E5+I5-I6 -> 86701 | H5: 入库 | I5: =SUM(J5:AO5) -> 0
H6: 出库 | I6: =SUM(J6:AO6) -> 1000 | Y6: 1000
A7: 2 | B7: 308孔型 | C7: M3*0.5-L6-M5*0.6 | D7: 1215 黄锌 | E7: 109648 | F7: pcs | G7: =E7+I7-I8 -> 109648 | H7: 入库 | I7: =SUM(J7:AO7) -> 0
H8: 出库 | I8: =SUM(J8:AO8) -> 0
A9: 3 | B9: 308孔型 | C9: M4*0.7-L8-M6.5*0.8 | D9: 1215 黄锌 | E9: 11200 | F9: pcs | G9: =E9+I9-I10 -> 11200 | H9: 入库 | I9: =SUM(J9:AO9) -> 0
H10: 出库 | I10: =SUM(J10:AO10) -> 0
A11: 4 | B11: 308孔型 | C11: M4*0.7-L8-M6.5*0.8 | D11: SUS303 | E11: 96122 | F11: pcs | G11: =E11+I11-I12 -> 90102 | H11: 入库 | I11: =SUM(J11:AO11) -> 0
H12: 出库 | I12: =SUM(J12:AO12) -> 6020 | Q12: 1000 | S12: 20 | AK12: 5000
A13: 5 | B13: 308孔型 | C13: M4*0.7-L8-M6.5*0.8 | D13: 1215 蓝锌 | E13: 28 | F13: pcs | G13: =E13+I13-I14 -> 28 | H13: 入库 | I13: =SUM(J13:AO13) -> 0
H14: 出库 | I14: =SUM(J14:AO14) -> 0
A15: 6 | B15: 3082型 | C15: M4*0.7-L8-M6.5*0.8(内六角) | D15: SUS303 | E15: 640 | F15: pcs | G15: =E15+I15-I16 -> 640 | H15: 入库 | I15: =SUM(J15:AO15) -> 0
H16: 出库 | I16: =SUM(J16:AO16) -> 0
A17: 7 | B17: 3082型 | C17: M4*0.7-L8-M6.5*0.8(内六角) | D17: 1215 蓝锌 | E17: 385 | F17: pcs | G17: =E17+I17-I18 -> 385 | H17: 入库 | I17: =SUM(J17:AO17) -> 0
H18: 出库 | I18: =SUM(J18:AO18) -> 0
A19: 8 | B19: 308孔型 | C19: M5*0.8-L10-M8*1.0 | D19: 1215 黄锌 | E19: 62898 | F19: pcs | G19: =E19+I19-I20 -> 62898 | H19: 入库 | I19: =SUM(J19:AO19) -> 0
H20: 出库 | I20: =SUM(J20:AO20) -> 0
A21: 9 | B21: 308孔型 | C21: M5*0.8-L10-M8*1.0 | D21: SUS303 | E21: 40962 | F21: pcs | G21: =E21+I21-I22 -> 40942 | H21: 入库 | I21: =SUM(J21:AO21) -> 0
H22: 出库 | I22: =SUM(J22:AO22) -> 20 | V22: 20
A23: 10 | B23: 3082型 | C23: M5*0.8-L10-M8*1.0（内六角） | D23: SUS303 | E23: 1250 | F23: pcs | G23: =E23+I23-I24 -> 1250 | H23: 入库 | I23: =SUM(J23:AO23) -> 0
H24: 出库 | I24: =SUM(J24:AO24) -> 0
A25: 11 | B25: 3082型 | C25: M5*0.8-L10-M8*1.0（内六角） | D25: 1215 蓝锌 | E25: 400 | F25: pcs | G25: =E25+I25-I26 -> 400 | H25: 入库 | I25: =SUM(J25:AO25) -> 0
H26: 出库 | I26: =SUM(J26:AO26) -> 0
A27: 12 | B27: 308孔型 | C27: M6*1.0-L12-M10*1.25 | D27: SUS303 | E27: 31653 | F27: pcs | G27: =E27+I27-I28 -> 28643 | H27: 入库 | I27: =SUM(J27:AO27) -> 0
H28: 出库 | I28: =SUM(J28:AO28) -> 3010 | L28: 2000 | Q28: 1000 | V28: 10
A29: 13 | B29: 308孔型 | C29: M6*1.0-L12-M10*1.25 | D29: 1215 黄锌 | E29: 17665 | F29: pcs | G29: =E29+I29-I30 -> 12665 | H29: 入库 | I29: =SUM(J29:AO29) -> 0
H30: 出库 | I30: =SUM(J30:AO30) -> 5000 | U30: 5000
A31: 14 | B31: 308孔型 | C31: M6*1.0-L12-M10*1.25 | D31: 1215 蓝锌 | E31: 15 | F31: pcs | G31: =E31+I31-I32 -> 15 | H31: 入库 | I31: =SUM(J31:AO31) -> 0
H32: 出库 | I32: =SUM(J32:AO32) -> 0
A33: 15 | B33: 3082型 | C33: M6*1.0-L12-M10*1.25（内六角） | D33: SUS303 | E33: 1060 | F33: pcs | G33: =E33+I33-I34 -> 1060 | H33: 入库 | I33: =SUM(J33:AO33) -> 0
H34: 出库 | I34: =SUM(J34:AO34) -> 0
A35: 16 | B35: 3082型 | C35: M6*1.0-L12-M10*1.25（内六角） | D35: 1215 蓝锌 | E35: 1810 | F35: pcs | G35: =E35+I35-I36 -> 1810 | H35: 入库 | I35: =SUM(J35:AO35) -> 0
H36: 出库 | I36: =SUM(J36:AO36) -> 0
A37: 17 | B37: 3082型 | C37: M6*1.0-L12-M10*1.25（内六角） | D37: 1215 黄锌 | E37: 5840 | F37: pcs | G37: =E37+I37-I38 -> 5840 | H37: 入库 | I37: =SUM(J37:AO37) -> 0
H38: 出库 | I38: =SUM(J38:AO38) -> 0
A39: 18 | B39: 308孔型 | C39: M8*1.25-L14-M12*1.5 | D39: SUS303 | E39: 41844 | F39: pcs | G39: =E39+I39-I40 -> 41832 | H39: 入库 | I39: =SUM(J39:AO39) -> 0
H40: 出库 | I40: =SUM(J40:AO40) -> 12 | P40: 2 | V40: 10
...

Sheet SKD440 型
A1: SKD440型库存明细
A2: 日期 | B2: ='302槽型'!B2 -> 46023 | D2: 本月入库统计 | H2: 每日入库统计 | J2: =SUMIF($H:$H,$H$65,J:J) -> 0 | K2: =SUMIF($H:$H,$H$65,K:K) -> 1035 | L2: =SUMIF($H:$H,$H$65,L:L) -> 0 | M2: =SUMIF($H:$H,$H$65,M:M) -> 0 | N2: =SUMIF($H:$H,$H$65,N:N) -> 9230 | O2: =SUMIF($H:$H,$H$65,O:O) -> 0 | P2: =SUMIF($H:$H,$H$65,P:P) -> 13260 | Q2: =SUMIF($H:$H,$H$65,Q:Q) -> 0 | R2: =SUMIF($H:$H,$H$65,R:R) -> 0 | S2: =SUMIF($H:$H,$H$65,S:S) -> 5365 | T2: =SUMIF($H:$H,$H$65,T:T) -> 0 | U2: =SUMIF($H:$H,$H$65,U:U) -> 0 | V2: =SUMIF($H:$H,$H$65,V:V) -> 0 | W2: =SUMIF($H:$H,$H$65,W:W) -> 147 | X2: =SUMIF($H:$H,$H$65,X:X) -> 0 | Y2: =SUMIF($H:$H,$H$65,Y:Y) -> 12690 | Z2: =SUMIF($H:$H,$H$65,Z:Z) -> 0 | AA2: =SUMIF($H:$H,$H$65,AA:AA) -> 0 | AB2: =SUMIF($H:$H,$H$65,AB:AB) -> 5080 | AC2: =SUMIF($H:$H,$H$65,AC:AC) -> 0 | AD2: =SUMIF($H:$H,$H$65,AD:AD) -> 0 | AE2: =SUMIF($H:$H,$H$65,AE:AE) -> 10100 | AF2: =SUMIF($H:$H,$H$65,AF:AF) -> 0 | AG2: =SUMIF($H:$H,$H$65,AG:AG) -> 2285 | AH2: =SUMIF($H:$H,$H$65,AH:AH) -> 0 | AI2: =SUMIF($H:$H,$H$65,AI:AI) -> 12790 | AJ2: =SUMIF($H:$H,$H$65,AJ:AJ) -> 0 | AK2: =SUMIF($H:$H,$H$65,AK:AK) -> 0 | AL2: =SUMIF($H:$H,$H$65,AL:AL) -> 0 | AM2: =SUMIF($H:$H,$H$65,AM:AM) -> 0 | AN2: =SUMIF($H:$H,$H$65,AN:AN) -> 0
D3: 本月出库统计 | H3: 每日出库统计 | J3: =SUMIF($H:$H,$H$66,J:J) -> 0 | K3: =SUMIF($H:$H,$H$66,K:K) -> 100 | L3: =SUMIF($H:$H,$H$66,L:L) -> 100 | M3: =SUMIF($H:$H,$H$66,M:M) -> 0 | N3: =SUMIF($H:$H,$H$66,N:N) -> 21590 | O3: =SUMIF($H:$H,$H$66,O:O) -> 42 | P3: =SUMIF($H:$H,$H$66,P:P) -> 12005 | Q3: =SUMIF($H:$H,$H$66,Q:Q) -> 42 | R3: =SUMIF($H:$H,$H$66,R:R) -> 0 | S3: =SUMIF($H:$H,$H$66,S:S) -> 210 | T3: =SUMIF($H:$H,$H$66,T:T) -> 0 | U3: =SUMIF($H:$H,$H$66,U:U) -> 105 | V3: =SUMIF($H:$H,$H$66,V:V) -> 500 | W3: =SUMIF($H:$H,$H$66,W:W) -> 300 | X3: =SUMIF($H:$H,$H$66,X:X) -> 0 | Y3: =SUMIF($H:$H,$H$66,Y:Y) -> 200 | Z3: =SUMIF($H:$H,$H$66,Z:Z) -> 0 | AA3: =SUMIF($H:$H,$H$66,AA:AA) -> 0 | AB3: =SUMIF($H:$H,$H$66,AB:AB) -> 8500 | AC3: =SUMIF($H:$H,$H$66,AC:AC) -> 200 | AD3: =SUMIF($H:$H,$H$66,AD:AD) -> 0 | AE3: =SUMIF($H:$H,$H$66,AE:AE) -> 0 | AF3: =SUMIF($H:$H,$H$66,AF:AF) -> 0 | AG3: =SUMIF($H:$H,$H$66,AG:AG) -> 0 | AH3: =SUMIF($H:$H,$H$66,AH:AH) -> 0 | AI3: =SUMIF($H:$H,$H$66,AI:AI) -> 4645 | AJ3: =SUMIF($H:$H,$H$66,AJ:AJ) -> 0 | AK3: =SUMIF($H:$H,$H$66,AK:AK) -> 8 | AL3: =SUMIF($H:$H,$H$66,AL:AL) -> 362 | AM3: =SUMIF($H:$H,$H$66,AM:AM) -> 0 | AN3: =SUMIF($H:$H,$H$66,AN:AN) -> 0
A4: 序号 | B4: 类别 | C4: 规格 | D4: 材质 | E4: 上月结存 | F4: 单位 | G4: 现货 | H4: 入/出库 | I4: 汇总 | J4: ='302槽型'!J4 -> 46023 | K4: ='302槽型'!K4 -> 46024 | L4: ='302槽型'!L4 -> 46025 | M4: ='302槽型'!M4 -> 46026 | N4: ='302槽型'!N4 -> 46027 | O4: ='302槽型'!O4 -> 46028 | P4: ='302槽型'!P4 -> 46029 | Q4: ='302槽型'!Q4 -> 46030 | ... AN4: ='302槽型'!AN4 -> 46053
A5: 1 | B5: SKD440型 | C5: M3*0.5-L6-OD6.0 | D5: SUS303 | E5: 9503 | F5: pcs | G5: =E5+I5-I6 -> 8903 | H5: 入库 | I5: =SUM(J5:AO5) -> 105 | W5: 105
H6: 出库 | I6: =SUM(J6:AO6) -> 705 | U6: 105 | V6: 100 | W6: 200 | AL6: 300
A7: 2 | B7: SKD440型 | C7: M3*0.5-L8-OD6.0 | D7: SUS303 | E7: 12840 | F7: pcs | G7: =E7+I7-I8 -> 12540 | H7: 入库 | I7: =SUM(J7:AO7) -> 0
H8: 出库 | I8: =SUM(J8:AO8) -> 300 | V8: 200 | W8: 100
A9: 3 | B9: SKD440型 | C9: M3*0.5-L10-OD6.0 | D9: SUS303 | E9: 5676 | F9: pcs | G9: =E9+I9-I10 -> 16951 | H9: 入库 | I9: =SUM(J9:AO9) -> 12725 | AE9: 10100 | AG9: 2285 | AI9: 340
H10: 出库 | I10: =SUM(J10:AO10) -> 1450 | N10: 1000 | V10: 200 | AC10: 200 | AL10: 50
A11: 4 | B11: SKD440型 | C11: M3*0.5-L8-OD6.0 | D11: C3604 | E11: 490 | F11: pcs | G11: =E11+I11-I12 -> 310 | H11: 入库 | I11: =SUM(J11:AO11) -> 0
H12: 出库 | I12: =SUM(J12:AO12) -> 180 | AI12: 180
A13: 5 | B13: SKD440型 | C13: M3*0.5-L10-OD6.0 | D13: C3604 | E13: 1910 | F13: pcs | G13: =E13+I13-I14 -> 1910 | H13: 入库 | I13: =SUM(J13:AO13) -> 0
H14: 出库 | I14: =SUM(J14:AO14) -> 0
A15: 6 | B15: SKD440型 | C15: M4*0.7-L6-OD8.0 | D15: SUS303 | E15: 4968 | F15: pcs | G15: =E15+I15-I16 -> 4968 | H15: 入库 | I15: =SUM(J15:AO15) -> 0
H16: 出库 | I16: =SUM(J16:AO16) -> 0
A17: 7 | B17: SKD440型 | C17: M4*0.7-L8-OD8.0 | D17: SUS303 | E17: 42820 | F17: pcs | G17: =E17+I17-I18 -> 31237 | H17: 入库 | I17: =SUM(J17:AO17) -> 0
H18: 出库 | I18: =SUM(J18:AO18) -> 11583 | N18: =11080+500 -> 11580 | AL18: 3
A19: 8 | B19: SKD440型 | C19: M4*0.7-L10-OD8.0 | D19: SUS303 | E19: 5396 | F19: pcs | G19: =E19+I19-I20 -> 5296 | H19: 入库 | I19: =SUM(J19:AO19) -> 0
H20: 出库 | I20: =SUM(J20:AO20) -> 100 | S20: 100
A21: 8 | B21: SKD440型 | C21: M4*0.7-L12-OD8.0 | D21: SUS303 | E21: 3839 | F21: pcs | G21: =E21+I21-I22 -> 3836 | H21: 入库 | I21: =SUM(J21:AO21) -> 0
H22: 出库 | I22: =SUM(J22:AO22) -> 3 | AL22: 3
A23: 9 | B23: SKD440型 | C23: M4*0.7-L8-OD8.0 | D23: C3604 | E23: 4140 | F23: pcs | G23: =E23+I23-I24 -> 4140 | H23: 入库 | I23: =SUM(J23:AO23) -> 0
H24: 出库 | I24: =SUM(J24:AO24) -> 0
A25: 10 | B25: SKD440型 | C25: M4*0.7-L12-OD8.0 | D25: 316材质 | E25: 1420 | F25: pcs | G25: =E25+I25-I26 -> 1420 | H25: 入库 | I25: =SUM(J25:AO25) -> 0
H26: 出库 | I26: =SUM(J26:AO26) -> 0
A27: 10 | B27: SKD440型 | C27: M4*0.7-L12-OD8.0 | D27: C3604 | E27: 192 | F27: pcs | G27: =E27+I27-I28 -> 192 | H27: 入库 | I27: =SUM(J27:AO27) -> 0
H28: 出库 | I28: =SUM(J28:AO28) -> 0
A29: 11 | B29: SKD440型 | C29: M4*0.7-L10-OD8.0 | D29: C3604 | E29: 6848 | F29: pcs | G29: =E29+I29-I30 -> 6848 | H29: 入库 | I29: =SUM(J29:AO29) -> 0
H30: 出库 | I30: =SUM(J30:AO30) -> 0
A31: 12 | B31: SKD440型 | C31: M5*0.8-L15-OD10.0 | D31: SUS303 | E31: 5075 | F31: pcs | G31: =E31+I31-I32 -> 5075 | H31: 入库 | I31: =SUM(J31:AO31) -> 0
H32: 出库 | I32: =SUM(J32:AO32) -> 0
A33: 13 | B33: SKD440型 | C33: M5*0.8-L8-OD10.0 | D33: SUS303 | E33: 8404 | F33: pcs | G33: =E33+I33-I34 -> 10379 | H33: 入库 | I33: =SUM(J33:AO33) -> 1975 | S33: 1975
H34: 出库 | I34: =SUM(J34:AO34) -> 0
A35: 14 | B35: SKD440型 | C35: M5*0.8-L12-OD10.0 | D35: SUS303 | E35: 6294 | F35: pcs | G35: =E35+I35-I36 -> 9681 | H35: 入库 | I35: =SUM(J35:AO35) -> 3390 | S35: 3390
H36: 出库 | I36: =SUM(J36:AO36) -> 3 | AL36: 3
A37: 15 | B37: SKD440型 | C37: M5*0.8-L10-OD10.0 | D37: SUS303 | E37: 11766 | F37: pcs | G37: =E37+I37-I38 -> 11766 | H37: 入库 | I37: =SUM(J37:AO37) -> 0
H38: 出库 | I38: =SUM(J38:AO38) -> 0
A39: 16 | B39: SKD440型 | C39: M5*0.8-L18-OD10.0 | D39: SUS303 | E39: 848 | F39: pcs | G39: =E39+I39-I40 -> 848 | H39: 入库 | I39: =SUM(J39:AO39) -> 0
H40: 出库 | I40: =SUM(J40:AO40) -> 0
...

Sheet 公制 插销螺套
A1: 插销螺套库存明细
A2: 日期 | B2: ='302槽型'!B2 -> 46023 | D2: 本月入库统计 | H2: 每日入库统计
D3: 本月出库统计 | H3: 每日出库统计
A4: 序号 | B4: 类别 | C4: 规格 | D4: 材质 | E4: 上月结存 | F4: 单位 | G4: 现库存 | H4: 入/出库 | I4: 汇总 | J4: ='302槽型'!J4 -> 46023 | K4: ='302槽型'!K4 -> 46024 | L4: ='302槽型'!L4 -> 46025 | M4: ='302槽型'!M4 -> 46026 | N4: ='302槽型'!N4 -> 46027 | O4: ='302槽型'!O4 -> 46028 | P4: ='302槽型'!P4 -> 46029 | Q4: ='302槽型'!Q4 -> 46030 | ... AN4: ='302槽型'!AN4 -> 46053 | AQ4: 备注
A5: =MAX(A4:$A$4)+1 -> 1 | B5: 轻型插销螺套 | C5: M2*0.4-L3-M4*0.7 | D5: SUS303 | E5: 440 | F5: pcs | G5: =E5+I5-I6 -> 440 | H5: 入库 | I5: =SUM(J5:AO5) -> 0
H6: 出库 | I6: =SUM(J6:AO6) -> 0
A7: =MAX(A$4:$A6)+1 -> 2 | B7: 重型插销螺套 | C7: M2*0.4-L3-M5*0.8 | D7: SUS303 | E7: 28 | F7: pcs | G7: =E7+I7-I8 -> 28 | H7: 入库 | I7: =SUM(J7:AO7) -> 0
H8: 出库 | I8: =SUM(J8:AO8) -> 0
A9: =MAX(A$4:$A8)+1 -> 3 | B9: 轻型插销螺套 | C9: M2.5*0.45-L3.8-M4.5*0.75 | D9: SUS303 | E9: 503 | F9: pcs | G9: =E9+I9-I10 -> 503 | H9: 入库 | I9: =SUM(J9:AO9) -> 0
H10: 出库 | I10: =SUM(J10:AO10) -> 0
A11: =MAX(A$4:$A10)+1 -> 4 | B11: 轻型插销螺套 | C11: M2.5*0.45-L3-M5*0.8 | D11: SUS303 | E11: 80 | F11: pcs | G11: =E11+I11-I12 -> 80 | H11: 入库 | I11: =SUM(J11:AO11) -> 0
H12: 出库 | I12: =SUM(J12:AO12) -> 0
A13: =MAX(A$4:$A12)+1 -> 5 | B13: 轻型插销螺套 | C13: M3*0.5-L4.2-M5*0.8 | D13: SUS303 | E13: 1101 | F13: pcs | G13: =E13+I13-I14 -> 20751 | H13: 入库 | I13: =SUM(J13:AO13) -> 19850 | S13: 12870 | AF13: 6980
H14: 出库 | I14: =SUM(J14:AO14) -> 200 | AL14: 200
A15: =MAX(A$4:$A14)+1 -> 6 | B15: 轻型插销螺套 | C15: M3*0.5-L6-M5*0.8 | D15: SUS303 | E15: 24365 | F15: pcs | G15: =E15+I15-I16 -> 39790 | H15: 入库 | I15: =SUM(J15:AO15) -> 15425 | Q15: 15425
H16: 出库 | I16: =SUM(J16:AO16) -> 0
A17: =MAX(A$4:$A16)+1 -> 7 | B17: 轻型插销螺套 | C17: M3*0.5-L5-M5*0.8 | D17: SUS303 | E17: 2680 | F17: pcs | G17: =E17+I17-I18 -> 2680 | H17: 入库 | I17: =SUM(J17:AO17) -> 0
H18: 出库 | I18: =SUM(J18:AO18) -> 0
A19: =MAX(A$4:$A18)+1 -> 8 | B19: 轻型插销螺套 | C19: M3*0.5-L8-M5*0.8 | D19: SUS303 | E19: 12211 | F19: pcs | G19: =E19+I19-I20 -> 11711 | H19: 入库 | I19: =SUM(J19:AO19) -> 0
H20: 出库 | I20: =SUM(J20:AO20) -> 500 | N20: 500
A21: =MAX(A$4:$A20)+1 -> 9 | B21: 轻型插销螺套 | C21: M3*0.5-L10-M5*0.8 | D21: SUS303 | E21: 14880 | F21: pcs | G21: =E21+I21-I22 -> 14380 | H21: 入库 | I21: =SUM(J21:AO21) -> 0
H22: 出库 | I22: =SUM(J22:AO22) -> 500 | N22: 500
A23: =MAX(A$4:$A22)+1 -> 10 | B23: 轻型插销螺套 | C23: M4*0.7-L5.2-M6*0.75 | D23: SUS303 | E23: 46976 | F23: pcs | G23: =E23+I23-I24 -> 75176 | H23: 入库 | I23: =SUM(J23:AO23) -> 28200 | K23: 5000 | W23: 6600 | AM23: 16600
H24: 出库 | I24: =SUM(J24:AO24) -> 0
A25: =MAX(A$4:$A24)+1 -> 11 | B25: 轻型插销螺套 | C25: M4*0.7-L6-M6*0.75 | D25: SUS303 | E25: 3205 | F25: pcs | G25: =E25+I25-I26 -> 3205 | H25: 入库 | I25: =SUM(J25:AO25) -> 0
H26: 出库 | I26: =SUM(J26:AO26) -> 0
A27: =MAX(A$4:$A26)+1 -> 12 | B27: 轻型插销螺套 | C27: M4*0.7-L8-M6*0.75 | D27: SUS303 | E27: 22913 | F27: pcs | G27: =E27+I27-I28 -> 22873 | H27: 入库 | I27: =SUM(J27:AO27) -> 0
H28: 出库 | I28: =SUM(J28:AO28) -> 40 | AG28: 40
A29: =MAX(A$4:$A28)+1 -> 13 | B29: 轻型插销螺套 | C29: M4*0.7-L10-M6*0.75 | D29: SUS303 | E29: 9830 | F29: pcs | G29: =E29+I29-I30 -> 9330 | H29: 入库 | I29: =SUM(J29:AO29) -> 0
H30: 出库 | I30: =SUM(J30:AO30) -> 500 | AF30: 500
A31: =MAX(A$4:$A30)+1 -> 14 | B31: 轻型插销螺套 | C31: M4*0.7-L12-M6*0.75 | D31: SUS303 | E31: 9665 | F31: pcs | G31: =E31+I31-I32 -> 9665 | H31: 入库 | I31: =SUM(J31:AO31) -> 0
H32: 出库 | I32: =SUM(J32:AO32) -> 0
A33: =MAX(A$4:$A32)+1 -> 15 | B33: 轻型插销螺套 | C33: M4*0.7-L15-M6*0.75 | D33: SUS303 | E33: 0 | F33: pcs | G33: =E33+I33-I34 -> 0 | H33: 入库 | I33: =SUM(J33:AO33) -> 0
H34: 出库 | I34: =SUM(J34:AO34) -> 0
A35: =MAX(A$4:$A34)+1 -> 16 | B35: 轻型插销螺套 | C35: M5*0.8-L6-M8*1.25 | D35: SUS303 | E35: 0 | F35: pcs | G35: =E35+I35-I36 -> 1500 | H35: 入库 | I35: =SUM(J35:AO35) -> 1500 | W35: 1500
H36: 出库 | I36: =SUM(J36:AO36) -> 0
A37: =MAX(A$4:$A36)+1 -> 17 | B37: 轻型插销螺套 | C37: M5*0.8-L8-M8*1.25 | D37: SUS303 | E37: 47327 | F37: pcs | G37: =E37+I37-I38 -> 53672 | H37: 入库 | I37: =SUM(J37:AO37) -> 12365 | K37: 12365
H38: 出库 | I38: =SUM(J38:AO38) -> 6020 | S38: 6020
A39: =MAX(A$4:$A38)+1 -> 18 | B39: 轻型插销螺套 | C39: M5*0.8-L10-M8*1.25 | D39: SUS303 | E39: 1346 | F39: pcs | G39: =E39+I39-I40 -> 7501 | H39: 入库 | I39: =SUM(J39:AO39) -> 6155 | R39: 3215 | AI39: 2940
H40: 出库 | I40: =SUM(J40:AO40) -> 0
...

Sheet  自锁 插销螺套 
A1: 插销螺套库存明细
A2: 日期 | B2: ='302槽型'!B2 -> 46023 | D2: 本月入库统计 | H2: 每日入库统计
D3: 本月出库统计 | H3: 每日出库统计
A4: 序号 | B4: 类别 | C4: 规格 | D4: 材质 | E4: 上月结存 | F4: 单位 | G4: 现库存 | H4: 入/出库 | I4: 汇总 | J4: ='302槽型'!J4 -> 46023 | K4: ='302槽型'!K4 -> 46024 | L4: ='302槽型'!L4 -> 46025 | M4: ='302槽型'!M4 -> 46026 | N4: ='302槽型'!N4 -> 46027 | O4: ='302槽型'!O4 -> 46028 | P4: ='302槽型'!P4 -> 46029 | Q4: ='302槽型'!Q4 -> 46030 | ... AN4: ='302槽型'!AN4 -> 46053 | AQ4: 备注
A5: =MAX(A$4:$A4)+1 -> 1 | B5: 自锁插销螺套 | C5: M3*0.5-L4.2-M5*0.8 | D5: SUS303 | E5: 1205 | F5: pcs | G5: =E5+I5-I6 -> 1205 | H5: 入库 | I5: =SUM(J5:AO5) -> 0
H6: 出库 | I6: =SUM(J6:AO6) -> 0
A7: =MAX(A$4:$A6)+1 -> 2 | B7: 自锁插销螺套 | C7: M4*0.7-L5.2-M6*0.75 | D7: SUS303 | E7: 6995 | F7: pcs | G7: =E7+I7-I8 -> 6995 | H7: 入库 | I7: =SUM(J7:AO7) -> 0
H8: 出库 | I8: =SUM(J8:AO8) -> 0
A9: =MAX(A$4:$A8)+1 -> 3 | B9: 自锁插销螺套 | C9: M5*0.8-L8-M8*1.25 | D9: SUS303 | E9: 1559 | F9: pcs | G9: =E9+I9-I10 -> 1559 | H9: 入库 | I9: =SUM(J9:AO9) -> 0
H10: 出库 | I10: =SUM(J10:AO10) -> 0
A11: =MAX(A$4:$A10)+1 -> 4 | B11: 自锁插销螺套 | C11: M6*1.0-L10-M10*1.25 | D11: SUS303 | E11: 315 | F11: pcs | G11: =E11+I11-I12 -> 315 | H11: 入库 | I11: =SUM(J11:AO11) -> 0
H12: 出库 | I12: =SUM(J12:AO12) -> 0
A13: =MAX(A$4:$A12)+1 -> 5 | B13: 自锁插销螺套 | C13: M6*1.0-L12-M12*1.25 | D13: SUS303 | E13: 1338 | F13: pcs | G13: =E13+I13-I14 -> 1338 | H13: 入库 | I13: =SUM(J13:AO13) -> 0
H14: 出库 | I14: =SUM(J14:AO14) -> 0
A15: =MAX(A$4:$A14)+1 -> 6 | B15: 自锁插销螺套 | C15: M5*0.8-L10-M10*1.25 | D15: SUS303 | E15: 653 | F15: pcs | G15: =E15+I15-I16 -> 653 | H15: 入库 | I15: =SUM(J15:AO15) -> 0
H16: 出库 | I16: =SUM(J16:AO16) -> 0
A17: =MAX(A$4:$A16)+1 -> 7 | B17: 自锁插销螺套 | C17: M8*1.25-L12-M12*1.25 | D17: SUS303 | E17: 25 | F17: pcs | G17: =E17+I17-I18 -> 25 | H17: 入库 | I17: =SUM(J17:AO17) -> 0
H18: 出库 | I18: =SUM(J18:AO18) -> 0
A19: =MAX(A$4:$A18)+1 -> 8 | B19: 自锁插销螺套 | C19: M10*1.5-L14-M14*1.5 | D19: SUS303 | E19: 475 | F19: pcs | G19: =E19+I19-I20 -> 475 | H19: 入库 | I19: =SUM(J19:AO19) -> 0
H20: 出库 | I20: =SUM(J20:AO20) -> 0
A21: =MAX(A$4:$A20)+1 -> 9 | B21: 自锁插销螺套 | C21: M12*1.75-L18-M18*1.5 | D21: SUS303 | E21: 191 | F21: pcs | G21: =E21+I21-I22 -> 191 | H21: 入库 | I21: =SUM(J21:AO21) -> 0
H22: 出库 | I22: =SUM(J22:AO22) -> 0
A23: =MAX(A$4:$A22)+1 -> 10 | B23: 自锁插销螺套 | C23: M12*1.75-L16-M16*1.5（线割） | D23: SUS303 | E23: 172 | F23: pcs | G23: =E23+I23-I24 -> 172 | H23: 入库 | I23: =SUM(J23:AO23) -> 0
H24: 出库 | I24: =SUM(J24:AO24) -> 0
A25: =MAX(A$4:$A24)+1 -> 11 | B25: 自锁插销螺套 | C25: M16*2.0-L22-M22*1.5 | D25: SUS303 | E25: 55 | F25: pcs | G25: =E25+I25-I26 -> 55 | H25: 入库 | I25: =SUM(J25:AO25) -> 0
H26: 出库 | I26: =SUM(J26:AO26) -> 0
A27: =MAX(A$4:$A26)+1 -> 12 | B27: 自锁插销螺套 | C27: 1/2--L17.2-3/4- | D27: SUS303 | E27: 564 | F27: pcs | G27: =E27+I27-I28 -> 564 | H27: 入库 | I27: =SUM(J27:AO27) -> 0
H28: 出库 | I28: =SUM(J28:AO28) -> 0
A29: =MAX(A$4:$A28)+1 -> 13 | E29: 0 | F29: pcs | G29: =E29+I29-I30 -> 0 | H29: 入库 | I29: =SUM(J29:AO29) -> 0
H30: 出库 | I30: =SUM(J30:AO30) -> 0
A31: =MAX(A$4:$A30)+1 -> 14 | E31: 0 | F31: pcs | G31: =E31+I31-I32 -> 0 | H31: 入库 | I31: =SUM(J31:AO31) -> 0
H32: 出库 | I32: =SUM(J32:AO32) -> 0
A33: =MAX(A$4:$A32)+1 -> 15 | E33: 0 | F33: pcs | G33: =E33+I33-I34 -> 0 | H33: 入库 | I33: =SUM(J33:AO33) -> 0
H34: 出库 | I34: =SUM(J34:AO34) -> 0
A35: =MAX(A$4:$A34)+1 -> 16 | E35: 0 | F35: pcs | G35: =E35+I35-I36 -> 0 | H35: 入库 | I35: =SUM(J35:AO35) -> 0
H36: 出库 | I36: =SUM(J36:AO36) -> 0
A37: =MAX(A$4:$A36)+1 -> 17 | F37: pcs | G37: =E37+I37-I38 -> 0 | H37: 入库 | I37: =SUM(J37:AO37) -> 0
H38: 出库 | I38: =SUM(J38:AO38) -> 0
A39: =MAX(A$4:$A38)+1 -> 18 | F39: pcs | G39: =E39+I39-I40 -> 0 | H39: 入库 | I39: =SUM(J39:AO39) -> 0
H40: 出库 | I40: =SUM(J40:AO40) -> 0
...

Sheet 美-英制 插销螺套 
A1: 插销螺套库存明细
A2: 日期 | B2: ='302槽型'!B2 -> 46023 | D2: 本月入库统计 | H2: 每日入库统计
D3: 本月出库统计 | H3: 每日出库统计
A4: 序号 | B4: 类别 | C4: 规格 | D4: 材质 | E4: 上月结存 | F4: 单位 | G4: 现库存 | H4: 入/出库 | I4: 汇总 | J4: ='302槽型'!J4 -> 46023 | K4: ='302槽型'!K4 -> 46024 | L4: ='302槽型'!L4 -> 46025 | M4: ='302槽型'!M4 -> 46026 | N4: ='302槽型'!N4 -> 46027 | O4: ='302槽型'!O4 -> 46028 | P4: ='302槽型'!P4 -> 46029 | Q4: ='302槽型'!Q4 -> 46030 | ... AN4: ='302槽型'!AN4 -> 46053 | AQ4: 备注
A5: =MAX(A$4:$A4)+1 -> 1 | B5: 美/英制插销螺套 | C5: 7/8-14-L15-M27*1.5 | D5: SUS303 | E5: 34 | F5: pcs | G5: =E5+I5-I6 -> 34 | H5: 入库 | I5: =SUM(J5:AO5) -> 0
H6: 出库 | I6: =SUM(J6:AO6) -> 0
A7: =MAX(A$4:$A6)+1 -> 2 | B7: 美/英制插销螺套 | C7: 3/8-16-L16-M16*1.5 | D7: SUS303 | E7: 210 | F7: pcs | G7: =E7+I7-I8 -> 210 | H7: 入库 | I7: =SUM(J7:AO7) -> 0
H8: 出库 | I8: =SUM(J8:AO8) -> 0
A9: =MAX(A$4:$A8)+1 -> 3 | B9: 美/英制插销螺套 | C9: 7/16-20-L28-M16*1.5 | D9: SUS303 | E9: 44 | F9: pcs | G9: =E9+I9-I10 -> 44 | H9: 入库 | I9: =SUM(J9:AO9) -> 0
H10: 出库 | I10: =SUM(J10:AO10) -> 0
A11: =MAX(A$4:$A10)+1 -> 4 | B11: 美/英制插销螺套 | C11: 7/16-20-L27-M16*1.5 | D11: SUS303 | E11: 4 | F11: pcs | G11: =E11+I11-I12 -> 4 | H11: 入库 | I11: =SUM(J11:AO11) -> 0
H12: 出库 | I12: =SUM(J12:AO12) -> 0
A13: =MAX(A$4:$A12)+1 -> 5 | B13: 美/英制插销螺套 | C13: 3/8-16-L15-M18*1.5 | D13: SUS303 | E13: 19 | F13: pcs | G13: =E13+I13-I14 -> 19 | H13: 入库 | I13: =SUM(J13:AO13) -> 0
H14: 出库 | I14: =SUM(J14:AO14) -> 0
A15: =MAX(A$4:$A14)+1 -> 6 | B15: 美/英制插销螺套 | C15: 1/2-13-L20-M18*1.5 | D15: SUS303 | E15: 69 | F15: pcs | G15: =E15+I15-I16 -> 69 | H15: 入库 | I15: =SUM(J15:AO15) -> 0
H16: 出库 | I16: =SUM(J16:AO16) -> 0
A17: =MAX(A$4:$A16)+1 -> 7 | B17: 美/英制插销螺套 | C17: 1/2-13-L16.5-11/16-12 | D17: SUS303 | E17: 21 | F17: pcs | G17: =E17+I17-I18 -> 21 | H17: 入库 | I17: =SUM(J17:AO17) -> 0
H18: 出库 | I18: =SUM(J18:AO18) -> 0
A19: =MAX(A$4:$A18)+1 -> 8 | B19: 美标重型插销螺套 | C19: 1/4-20-L10.9-7/16-14 | D19: SUS303 | E19: 165 | F19: pcs | G19: =E19+I19-I20 -> 165 | H19: 入库 | I19: =SUM(J19:AO19) -> 0
H20: 出库 | I20: =SUM(J20:AO20) -> 0
A21: =MAX(A$4:$A20)+1 -> 9 | B21: 美标重型插销螺套 | C21: 5/16-18-L12.3-1/2-13 | D21: SUS303 | E21: 322 | F21: pcs | G21: =E21+I21-I22 -> 322 | H21: 入库 | I21: =SUM(J21:AO21) -> 0
H22: 出库 | I22: =SUM(J22:AO22) -> 0
A23: =MAX(A$4:$A22)+1 -> 10 | B23: 美标重型插销螺套 | C23: 1/4-20-L12.3-7/16-14 | D23: SUS303 | E23: 449 | F23: pcs | G23: =E23+I23-I24 -> 449 | H23: 入库 | I23: =SUM(J23:AO23) -> 0
H24: 出库 | I24: =SUM(J24:AO24) -> 0
A25: =MAX(A$4:$A24)+1 -> 11 | B25: 美标轻型插销螺套 | C25: 1/4-20-L9.38-3/8-16（不过环规） | D25: SUS303 | E25: 934 | F25: pcs | G25: =E25+I25-I26 -> 929 | H25: 入库 | I25: =SUM(J25:AO25) -> 0
H26: 出库 | I26: =SUM(J26:AO26) -> 5 | AI26: 5
A27: =MAX(A$4:$A26)+1 -> 12 | B27: 美标轻型插销螺套 | C27: 1/4-20-L9.38-3/8-16（可过环规） | D27: SUS303 | E27: 2097 | F27: pcs | G27: =E27+I27-I28 -> 2047 | H27: 入库 | I27: =SUM(J27:AO27) -> 0
H28: 出库 | I28: =SUM(J28:AO28) -> 50 | L28: 50
A29: =MAX(A$4:$A28)+1 -> 13 | B29: 美/英制插销螺套 | C29: 8-32-L5.59-1/4-28 | D29: SUS303 | E29: 1985 | F29: pcs | G29: =E29+I29-I30 -> 1981 | H29: 入库 | I29: =SUM(J29:AO29) -> 0
H30: 出库 | I30: =SUM(J30:AO30) -> 4 | AJ30: 4
A31: =MAX(A$4:$A30)+1 -> 14 | B31: 美标轻型插销螺套 | C31: 3/8-16-L12.7-1/2-13 | D31: SUS303 | E31: 652 | F31: pcs | G31: =E31+I31-I32 -> 652 | H31: 入库 | I31: =SUM(J31:AO31) -> 0
H32: 出库 | I32: =SUM(J32:AO32) -> 0
A33: =MAX(A$4:$A32)+1 -> 15 | B33: 美标重型插销螺套 | C33: 3/8-16-L12.7-9/16-12（不过环规） | D33: SUS303 | E33: 2314 | F33: pcs | G33: =E33+I33-I34 -> 2214 | H33: 入库 | I33: =SUM(J33:AO33) -> 0
H34: 出库 | I34: =SUM(J34:AO34) -> 100 | X34: 100
A35: =MAX(A$4:$A34)+1 -> 16 | B35: 美标重型插销螺套 | C35: 3/8-16-L12.7-9/16-12（可过环规） | D35: SUS303 | E35: 1979 | F35: pcs | G35: =E35+I35-I36 -> 1979 | H35: 入库 | I35: =SUM(J35:AO35) -> 0
H36: 出库 | I36: =SUM(J36:AO36) -> 0
A37: =MAX(A$4:$A36)+1 -> 17 | B37: 美/英制插销螺套 | C37: 5/8-11-L15.75-1/2-20 | D37: SUS303 | E37: 789 | F37: pcs | G37: =E37+I37-I38 -> 789 | H37: 入库 | I37: =SUM(J37:AO37) -> 0
H38: 出库 | I38: =SUM(J38:AO38) -> 0
A39: =MAX(A$4:$A38)+1 -> 18 | B39: 美标轻型插销螺套 | C39: 3/8-16-L14-1/2-13 | D39: SUS303 | E39: 2091 | F39: pcs | G39: =E39+I39-I40 -> 791 | H39: 入库 | I39: =SUM(J39:AO39) -> 0
H40: 出库 | I40: =SUM(J40:AO40) -> 1300 | V40: 1300
...

Sheet 337 338 盲孔型
A1: 337/338型库存明细
A2: 日期 | B2: ='302槽型'!B2 -> 46023 | D2: 本月入库统计 | H2: 每日入库统计 | J2: =SUMIF($H:$H,#REF!,J:J) -> 0 | K2: =SUMIF($H:$H,#REF!,K:K) -> 0 | L2: =SUMIF($H:$H,#REF!,L:L) -> 0 | M2: =SUMIF($H:$H,#REF!,M:M) -> 0 | N2: =SUMIF($H:$H,#REF!,N:N) -> 0 | O2: =SUMIF($H:$H,#REF!,O:O) -> 0 | P2: =SUMIF($H:$H,#REF!,P:P) -> 0 | Q2: =SUMIF($H:$H,#REF!,Q:Q) -> 0 | R2: =SUMIF($H:$H,#REF!,R:R) -> 0 | S2: =SUMIF($H:$H,#REF!,S:S) -> 0 | T2: =SUMIF($H:$H,#REF!,T:T) -> 0 | U2: =SUMIF($H:$H,#REF!,U:U) -> 0 | V2: =SUMIF($H:$H,#REF!,V:V) -> 0 | W2: =SUMIF($H:$H,#REF!,W:W) -> 0 | X2: =SUMIF($H:$H,#REF!,X:X) -> 0 | Y2: =SUMIF($H:$H,#REF!,Y:Y) -> 0
D3: 本月出库统计 | H3: 每日出库统计 | J3: =SUMIF($H:$H,#REF!,J:J) -> 0 | K3: =SUMIF($H:$H,#REF!,K:K) -> 0 | L3: =SUMIF($H:$H,#REF!,L:L) -> 0 | M3: =SUMIF($H:$H,#REF!,M:M) -> 0 | N3: =SUMIF($H:$H,#REF!,N:N) -> 0 | O3: =SUMIF($H:$H,#REF!,O:O) -> 0 | P3: =SUMIF($H:$H,#REF!,P:P) -> 0 | Q3: =SUMIF($H:$H,#REF!,Q:Q) -> 0 | R3: =SUMIF($H:$H,#REF!,R:R) -> 0 | S3: =SUMIF($H:$H,#REF!,S:S) -> 0 | T3: =SUMIF($H:$H,#REF!,T:T) -> 0 | U3: =SUMIF($H:$H,#REF!,U:U) -> 0 | V3: =SUMIF($H:$H,#REF!,V:V) -> 0 | W3: =SUMIF($H:$H,#REF!,W:W) -> 0 | X3: =SUMIF($H:$H,#REF!,X:X) -> 0 | Y3: =SUMIF($H:$H,#REF!,Y:Y) -> 0
A4: 序号 | B4: 类别 | C4: 规格 | D4: 材质 | E4: 上月结存 | F4: 单位 | G4: 现库存 | H4: 入/出库 | I4: 汇总 | J4: ='302槽型'!J4 -> 46023 | K4: ='302槽型'!K4 -> 46024 | L4: ='302槽型'!L4 -> 46025 | M4: ='302槽型'!M4 -> 46026 | N4: ='302槽型'!N4 -> 46027 | O4: ='302槽型'!O4 -> 46028 | P4: ='302槽型'!P4 -> 46029 | Q4: ='302槽型'!Q4 -> 46030 | ... AN4: ='302槽型'!AN4 -> 46053
A5: 1 | B5: 337型 | C5: M3*0.5-L4-M5*0.6 | D5: SUS303 | E5: 29512 | F5: pcs | G5: =E5+I5-I6 -> 27492 | H5: 入库 | I5: =SUM(J5:AO5) -> 4980 | S5: 4980
H6: 出库 | I6: =SUM(J6:AO6) -> 7000 | K6: 500 | Q6: 5000 | S6: 1000 | Y6: 300 | AF6: 200
A7: 2 | B7: 337型 | C7: M4*0.7-L6-M6.5*0.8 | D7: SUS303 | E7: 2075 | F7: pcs | G7: =E7+I7-I8 -> 875 | H7: 入库 | I7: =SUM(J7:AO7) -> 9875 | S7: 2075 | AI7: 7800
H8: 出库 | I8: =SUM(J8:AO8) -> 11075 | Q8: 2075 | S8: 2000 | AI8: 3000 | AK8: 4000
A9: 2 | B9: 337型 | C9: M4*0.7-L6-M6.5*0.8(侧孔2.5) | D9: SUS303 | E9: 0 | F9: pcs | G9: =E9+I9-I10 -> 0 | H9: 入库 | I9: =SUM(J9:AO9) -> 0
H10: 出库 | I10: =SUM(J10:AO10) -> 0
A11: 3 | B11: 337型 | C11: M5*0.8-L5-M8*1.0 | D11: 304材质 | E11: 6847 | F11: pcs | G11: =E11+I11-I12 -> 6847 | H11: 入库 | I11: =SUM(J11:AO11) -> 0
H12: 出库 | I12: =SUM(J12:AO12) -> 0
A13: 3 | B13: 337型 | C13: M5*0.8-L7-M8*1.0 | D13: SUS303 | E13: 13073 | F13: pcs | G13: =E13+I13-I14 -> 5573 | H13: 入库 | I13: =SUM(J13:AO13) -> 0
H14: 出库 | I14: =SUM(J14:AO14) -> 7500 | K14: 500 | AI14: 3000 | AK14: 4000
A15: 4 | B15: 337型 | C15: M6*1.0-L6-M10*1.25 | D15: SUS303 | E15: 998 | F15: pcs | G15: =E15+I15-I16 -> 998 | H15: 入库 | I15: =SUM(J15:AO15) -> 0
H16: 出库 | I16: =SUM(J16:AO16) -> 0
A17: 4 | B17: 337型 | C17: M6*1.0-L8-M10*1.25 | D17: SUS303 | E17: 36121 | F17: pcs | G17: =E17+I17-I18 -> 30546 | H17: 入库 | I17: =SUM(J17:AO17) -> 8675 | S17: 5000 | AI17: 3675
H18: 出库 | I18: =SUM(J18:AO18) -> 14250 | N18: 250 | P18: 2000 | Q18: 5000 | AI18: 5000 | AK18: 2000
A19: 5 | B19: 337型 | C19: M6*1.0-L8-M10*1.25（全车制） | D19: SUS303 | E19: 10595 | F19: pcs | G19: =E19+I19-I20 -> 12495 | H19: 入库 | I19: =SUM(J19:AO19) -> 41900 | AB19: =11810+5205 -> 17015 | AC19: 4740 | AD19: 2880 | AE19: 6200 | AG19: 7270 | AI19: 3795
H20: 出库 | I20: =SUM(J20:AO20) -> 40000 | O20: 10000 | AB20: 12000 | AC20: 5000 | AD20: =5000+3000 -> 8000 | AE20: 5000
A21: 6 | B21: 337型 | C21: M8*1.25-L9-M12*1.5 | D21: SUS303 | E21: 3669 | F21: pcs | G21: =E21+I21-I22 -> 2569 | H21: 入库 | I21: =SUM(J21:AO21) -> 0
H22: 出库 | I22: =SUM(J22:AO22) -> 1100 | AC22: 1100
A23: 6 | B23: 337型 | C23: M8*1.25-L9-M12*1.5(全车制) | D23: SUS303 | E23: 1070 | F23: pcs | G23: =E23+I23-I24 -> 585 | H23: 入库 | I23: =SUM(J23:AO23) -> 19515 | Z23: 12645 | AB23: 4290 | AC23: 2580
H24: 出库 | I24: =SUM(J24:AO24) -> 20000 | Z24: 13000 | AC24: 5000 | AD24: 2000
A25: 7 | B25: 337型 | C25: M8*1.25-L8-M12*1.5 | D25: SUS303 | E25: 8318 | F25: pcs | G25: =E25+I25-I26 -> 8318 | H25: 入库 | I25: =SUM(J25:AO25) -> 0
H26: 出库 | I26: =SUM(J26:AO26) -> 0
A27: 8 | B27: 337型 | C27: M10*1.5-L10-M14*1.5 | D27: SUS303 | E27: 828 | F27: pcs | G27: =E27+I27-I28 -> 828 | H27: 入库 | I27: =SUM(J27:AO27) -> 0
H28: 出库 | I28: =SUM(J28:AO28) -> 0
A29: 9 | B29: 337型 | C29: M12*1.75-L12-M16*1.75 | D29: SUS303 | E29: 148 | F29: pcs | G29: =E29+I29-I30 -> 148 | H29: 入库 | I29: =SUM(J29:AO29) -> 0
H30: 出库 | I30: =SUM(J30:AO30) -> 0
A31: 10 | B31: 337型 | C31: M16*2.0-L14-M20*2.0 | D31: SUS303 | E31: 99 | F31: pcs | G31: =E31+I31-I32 -> 99 | H31: 入库 | I31: =SUM(J31:AO31) -> 0
H32: 出库 | I32: =SUM(J32:AO32) -> 0
A33: 10 | B33: 美标337型 | C33: 1/4-28-L8-M10*1.25(平底牙) | D33: SUS303 | E33: 50 | F33: pcs | G33: =E33+I33-I34 -> 50 | H33: 入库 | I33: =SUM(J33:AO33) -> 0
H34: 出库 | I34: =SUM(J34:AO34) -> 0
A36: 11 | B36: 338型 | C36: M3*0.5-L6-M5*0.6 | D36: SUS303 | E36: 19730 | F36: pcs | G36: =E36+I36-I37 -> 13530 | H36: 入库 | I36: =SUM(J36:AO36) -> 4000 | T36: 4000
H37: 出库 | I37: =SUM(J37:AO37) -> 10200 | N37: 4000 | P37: 1000 | AC37: 5200
A38: 12 | B38: 338型 | C38: M4*0.7-L8-M6.5*0.8 | D38: 316材质 | E38: 2480 | F38: pcs | G38: =E38+I38-I39 -> 2480 | H38: 入库 | I38: =SUM(J38:AO38) -> 600 | AF38: 600
H39: 出库 | I39: =SUM(J39:AO39) -> 600 | X39: 600
A40: 12 | B40: 338型 | C40: M4*0.7-L8-M6.5*0.8 | D40: SUS303 | E40: 6222 | F40: pcs | G40: =E40+I40-I41 -> 7160 | H40: 入库 | I40: =SUM(J40:AO40) -> 16160 | AG40: 16160
H41: 出库 | I41: =SUM(J41:AO41) -> 15222 | P41: 1000 | W41: 1000 | AC41: 4222 | AG41: 9000
...

Sheet 317 318 孔型 
A1: 317/318型库存明细
A2: 日期 | B2: ='302槽型'!B2 -> 46023 | D2: 本月入库统计 | H2: 每日入库统计 | J2: =SUMIF($H:$H,#REF!,J:J) -> 0 | K2: =SUMIF($H:$H,#REF!,K:K) -> 0 | L2: =SUMIF($H:$H,#REF!,L:L) -> 0 | M2: =SUMIF($H:$H,#REF!,M:M) -> 0 | N2: =SUMIF($H:$H,#REF!,N:N) -> 0 | O2: =SUMIF($H:$H,#REF!,O:O) -> 0 | P2: =SUMIF($H:$H,#REF!,P:P) -> 0 | Q2: =SUMIF($H:$H,#REF!,Q:Q) -> 0 | R2: =SUMIF($H:$H,#REF!,R:R) -> 0 | S2: =SUMIF($H:$H,#REF!,S:S) -> 0 | T2: =SUMIF($H:$H,#REF!,T:T) -> 0 | U2: =SUMIF($H:$H,#REF!,U:U) -> 0 | V2: =SUMIF($H:$H,#REF!,V:V) -> 0 | W2: =SUMIF($H:$H,#REF!,W:W) -> 0 | X2: =SUMIF($H:$H,#REF!,X:X) -> 0 | Y2: =SUMIF($H:$H,#REF!,Y:Y) -> 0
D3: 本月出库统计 | H3: 每日出库统计 | J3: =SUMIF($H:$H,#REF!,J:J) -> 0 | K3: =SUMIF($H:$H,#REF!,K:K) -> 0 | L3: =SUMIF($H:$H,#REF!,L:L) -> 0 | M3: =SUMIF($H:$H,#REF!,M:M) -> 0 | N3: =SUMIF($H:$H,#REF!,N:N) -> 0 | O3: =SUMIF($H:$H,#REF!,O:O) -> 0 | P3: =SUMIF($H:$H,#REF!,P:P) -> 0 | Q3: =SUMIF($H:$H,#REF!,Q:Q) -> 0 | R3: =SUMIF($H:$H,#REF!,R:R) -> 0 | S3: =SUMIF($H:$H,#REF!,S:S) -> 0 | T3: =SUMIF($H:$H,#REF!,T:T) -> 0 | U3: =SUMIF($H:$H,#REF!,U:U) -> 0 | V3: =SUMIF($H:$H,#REF!,V:V) -> 0 | W3: =SUMIF($H:$H,#REF!,W:W) -> 0 | X3: =SUMIF($H:$H,#REF!,X:X) -> 0 | Y3: =SUMIF($H:$H,#REF!,Y:Y) -> 0
A4: 序号 | B4: 类别 | C4: 规格 | D4: 材质 | E4: 上月结存 | F4: 单位 | G4: 现库存 | H4: 入/出库 | I4: 汇总 | J4: ='302槽型'!J4 -> 46023 | K4: ='302槽型'!K4 -> 46024 | L4: ='302槽型'!L4 -> 46025 | M4: ='302槽型'!M4 -> 46026 | N4: ='302槽型'!N4 -> 46027 | O4: ='302槽型'!O4 -> 46028 | P4: ='302槽型'!P4 -> 46029 | Q4: ='302槽型'!Q4 -> 46030 | ... AN4: ='302槽型'!AN4 -> 46053
A5: 1 | B5: 317孔型 | C5: M4*0.7-L6-M6.5-0.8 | D5: 316材质 | E5: 3270 | F5: pcs | G5: =E5+I5-I6 -> 3270 | H5: 入库 | I5: =SUM(J5:AO5) -> 0
H6: 出库 | I6: =SUM(J6:AO6) -> 0
A7: 2 | B7: 317孔型 | C7: M5*0.8-L7-M8*1.0 | D7: SUS303 | E7: 3686 | F7: pcs | G7: =E7+I7-I8 -> 3686 | H7: 入库 | I7: =SUM(J7:AO7) -> 0
H8: 出库 | I8: =SUM(J8:AO8) -> 0
A9: 3 | B9: 317孔型 | C9: M5*0.8-L10-M8*1.0 | D9: SUS303 | E9: 390 | F9: pcs | G9: =E9+I9-I10 -> 390 | H9: 入库 | I9: =SUM(J9:AO9) -> 0
H10: 出库 | I10: =SUM(J10:AO10) -> 0
A11: 4 | B11: 317孔型 | C11: M6*1.0-L8-M10*1.25 | D11: SUS303 | E11: 290 | F11: pcs | G11: =E11+I11-I12 -> 290 | H11: 入库 | I11: =SUM(J11:AO11) -> 0
H12: 出库 | I12: =SUM(J12:AO12) -> 0
A13: 5 | B13: 317孔型 | C13: M8*1.25-L9-M12*1.5 | D13: SUS303 | E13: 2380 | F13: pcs | G13: =E13+I13-I14 -> 2380 | H13: 入库 | I13: =SUM(J13:AO13) -> 0
H14: 出库 | I14: =SUM(J14:AO14) -> 0
A15: 6 | B15: 317孔型 | C15: M8*1.25-L9-M12*1.5 | D15: 1215黄锌 | E15: 2238 | F15: pcs | G15: =E15+I15-I16 -> 2238 | H15: 入库 | I15: =SUM(J15:AO15) -> 0
H16: 出库 | I16: =SUM(J16:AO16) -> 0
A17: 7 | B17: 317孔型 | C17: M12*1.75-L12-M16*1.75 | D17: SUS303 | E17: 271 | F17: pcs | G17: =E17+I17-I18 -> 271 | H17: 入库 | I17: =SUM(J17:AO17) -> 0
H18: 出库 | I18: =SUM(J18:AO18) -> 0
A19: 8 | B19: 318孔型 | C19: M8*1.25-L14-M12*1.5 | D19: 1215黄锌 | E19: 11000 | F19: pcs | G19: =E19+I19-I20 -> 11000 | H19: 入库 | I19: =SUM(J19:AO19) -> 0
H20: 出库 | I20: =SUM(J20:AO20) -> 0
A21: 9 | B21: 318孔型 | C21: M12*1.75-L22-M16*1.75 | D21: SUS303 | E21: 1138 | F21: pcs | G21: =E21+I21-I22 -> 1138 | H21: 入库 | I21: =SUM(J21:AO21) -> 0
H22: 出库 | I22: =SUM(J22:AO22) -> 0
A23: 10 | E23: 0 | F23: pcs | G23: =E23+I23-I24 -> 0 | H23: 入库 | I23: =SUM(J23:AO23) -> 0
H24: 出库 | I24: =SUM(J24:AO24) -> 0
A25: 11 | E25: 0 | F25: pcs | G25: =E25+I25-I26 -> 0 | H25: 入库 | I25: =SUM(J25:AO25) -> 0
H26: 出库 | I26: =SUM(J26:AO26) -> 0
A27: 12 | F27: pcs | G27: =E27+I27-I28 -> 0 | H27: 入库 | I27: =SUM(J27:AO27) -> 0
H28: 出库 | I28: =SUM(J28:AO28) -> 0
A29: 13 | F29: pcs | G29: =E29+I29-I30 -> 0 | H29: 入库 | I29: =SUM(J29:AO29) -> 0
H30: 出库 | I30: =SUM(J30:AO30) -> 0
A31: 14 | F31: pcs | G31: =E31+I31-I32 -> 0 | H31: 入库 | I31: =SUM(J31:AO31) -> 0
H32: 出库 | I32: =SUM(J32:AO32) -> 0
A33: 15 | F33: pcs | G33: =E33+I33-I34 -> 0 | H33: 入库 | I33: =SUM(J33:AO33) -> 0
H34: 出库 | I34: =SUM(J34:AO34) -> 0
A35: 16 | F35: pcs | G35: =E35+I35-I36 -> 0 | H35: 入库 | I35: =SUM(J35:AO35) -> 0
H36: 出库 | I36: =SUM(J36:AO36) -> 0
A37: 17 | F37: pcs | G37: =E37+I37-I38 -> 0 | H37: 入库 | I37: =SUM(J37:AO37) -> 0
H38: 出库 | I38: =SUM(J38:AO38) -> 0
A39: 18 | F39: pcs | G39: =E39+I39-I40 -> 0 | H39: 入库 | I39: =SUM(J39:AO39) -> 0
H40: 出库 | I40: =SUM(J40:AO40) -> 0
...

Sheet 302H307 308E型 
A1: 302H307308E型库存明细
A2: 日期 | B2: ='302槽型'!B2 -> 46023 | D2: 本月入库统计 | H2: 每日入库统计 | J2: =SUMIF($H:$H,#REF!,J:J) -> 0 | K2: =SUMIF($H:$H,#REF!,K:K) -> 0 | L2: =SUMIF($H:$H,#REF!,L:L) -> 0 | M2: =SUMIF($H:$H,#REF!,M:M) -> 0 | N2: =SUMIF($H:$H,#REF!,N:N) -> 0 | O2: =SUMIF($H:$H,#REF!,O:O) -> 0 | P2: =SUMIF($H:$H,#REF!,P:P) -> 0 | Q2: =SUMIF($H:$H,#REF!,Q:Q) -> 0 | R2: =SUMIF($H:$H,#REF!,R:R) -> 0 | S2: =SUMIF($H:$H,#REF!,S:S) -> 0 | T2: =SUMIF($H:$H,#REF!,T:T) -> 0 | U2: =SUMIF($H:$H,#REF!,U:U) -> 0 | V2: =SUMIF($H:$H,#REF!,V:V) -> 0 | W2: =SUMIF($H:$H,#REF!,W:W) -> 0 | X2: =SUMIF($H:$H,#REF!,X:X) -> 0 | Y2: =SUMIF($H:$H,#REF!,Y:Y) -> 0
D3: 本月出库统计 | H3: 每日出库统计 | J3: =SUMIF($H:$H,#REF!,J:J) -> 0 | K3: =SUMIF($H:$H,#REF!,K:K) -> 0 | L3: =SUMIF($H:$H,#REF!,L:L) -> 0 | M3: =SUMIF($H:$H,#REF!,M:M) -> 0 | N3: =SUMIF($H:$H,#REF!,N:N) -> 0 | O3: =SUMIF($H:$H,#REF!,O:O) -> 0 | P3: =SUMIF($H:$H,#REF!,P:P) -> 0 | Q3: =SUMIF($H:$H,#REF!,Q:Q) -> 0 | R3: =SUMIF($H:$H,#REF!,R:R) -> 0 | S3: =SUMIF($H:$H,#REF!,S:S) -> 0 | T3: =SUMIF($H:$H,#REF!,T:T) -> 0 | U3: =SUMIF($H:$H,#REF!,U:U) -> 0 | V3: =SUMIF($H:$H,#REF!,V:V) -> 0 | W3: =SUMIF($H:$H,#REF!,W:W) -> 0 | X3: =SUMIF($H:$H,#REF!,X:X) -> 0 | Y3: =SUMIF($H:$H,#REF!,Y:Y) -> 0
A4: 序号 | B4: 类别 | C4: 规格 | D4: 材质 | E4: 上月结存 | F4: 单位 | G4: 现库存 | H4: 入/出库 | I4: 汇总 | J4: ='302槽型'!J4 -> 46023 | K4: ='302槽型'!K4 -> 46024 | L4: ='302槽型'!L4 -> 46025 | M4: ='302槽型'!M4 -> 46026 | N4: ='302槽型'!N4 -> 46027 | O4: ='302槽型'!O4 -> 46028 | P4: ='302槽型'!P4 -> 46029 | Q4: ='302槽型'!Q4 -> 46030 | ... AN4: ='302槽型'!AN4 -> 46053
A5: 1 | B5: 302H型 | C5: M3*0.5-L7-M5*0.8-OD7.0 | D5: SUS303 | E5: 1320 | F5: pcs | G5: =E5+I5-I6 -> 12185 | H5: 入库 | I5: =SUM(J5:AO5) -> 13865 | L5: 5500 | S5: 4045 | Y5: 4320
H6: 出库 | I6: =SUM(J6:AO6) -> 3000 | L6: 3000
A7: 2 | B7: 302H型 | C7: M4*0.7-L9-M6.5*0.75-OD9.0 | D7: SUS303 | E7: 15410 | F7: pcs | G7: =E7+I7-I8 -> 10410 | H7: 入库 | I7: =SUM(J7:AO7) -> 0
H8: 出库 | I8: =SUM(J8:AO8) -> 5000 | R8: 1000 | W8: 1000 | Z8: 1000 | AC8: 2000
A9: 3 | B9: 302H型 | C9: M5*0.8-L11-M8*1.0-OD11.0 | D9: SUS303 | E9: 3186 | F9: pcs | G9: =E9+I9-I10 -> 3436 | H9: 入库 | I9: =SUM(J9:AO9) -> 650 | S9: 650
H10: 出库 | I10: =SUM(J10:AO10) -> 400 | AA10: 400
A11: 4 | B11: 302H型 | C11: M5*0.8-L12-M8*1.0-OD11.0 | D11: SUS303 | E11: 987 | F11: pcs | G11: =E11+I11-I12 -> 987 | H11: 入库 | I11: =SUM(J11:AO11) -> 0
H12: 出库 | I12: =SUM(J12:AO12) -> 0
A13: 5 | B13: 302H型 | C13: M6*1.0-L15.5-M10*1.5-OD13 | D13: SUS303 | E13: 7037 | F13: pcs | G13: =E13+I13-I14 -> 7037 | H13: 入库 | I13: =SUM(J13:AO13) -> 0
H14: 出库 | I14: =SUM(J14:AO14) -> 0
A15: 6 | B15: 302H型 | C15: M6*1.0-L15.5-M10*1.5-OD13 | D15: C3604 | E15: 1089 | F15: pcs | G15: =E15+I15-I16 -> 1089 | H15: 入库 | I15: =SUM(J15:AO15) -> 0
H16: 出库 | I16: =SUM(J16:AO16) -> 0
A17: 7 | B17: 302H型 | C17: M8*1.25-L16.5-M12*1.5-OD15 | D17: SUS303 | E17: 358 | F17: pcs | G17: =E17+I17-I18 -> 162 | H17: 入库 | I17: =SUM(J17:AO17) -> 0
H18: 出库 | I18: =SUM(J18:AO18) -> 196 | Q18: 90 | AI18: 6 | AL18: 100
A19: 8 | B19: 302H型 | C19: M10*1.5-L19.5-M14*1.5-OD17 | D19: SUS303 | E19: 1123 | F19: pcs | G19: =E19+I19-I20 -> 1123 | H19: 入库 | I19: =SUM(J19:AO19) -> 0
H20: 出库 | I20: =SUM(J20:AO20) -> 0
A21: 9 | B21: 302H型 | C21: M12*1.75-L22-M16*1.5-OD19 | D21: SUS303 | E21: 6164 | F21: pcs | G21: =E21+I21-I22 -> 5564 | H21: 入库 | I21: =SUM(J21:AO21) -> 0
H22: 出库 | I22: =SUM(J22:AO22) -> 600 | U22: 600
A23: 9 | B23: 302H型 | C23: M12*1.75-L35-M16*1.5-OD19 | D23: SUS303 | E23: 22 | F23: pcs | G23: =E23+I23-I24 -> 22 | H23: 入库 | I23: =SUM(J23:AO23) -> 0
H24: 出库 | I24: =SUM(J24:AO24) -> 0
A25: 10 | E25: 0 | F25: pcs | G25: =E25+I25-I26 -> 0 | H25: 入库 | I25: =SUM(J25:AO25) -> 0
H26: 出库 | I26: =SUM(J26:AO26) -> 0
A27: 11 | B27: 307E型 | C27: M3*0.5-L5-M5*0.6-OD7.0 | D27: SUS303 | E27: 3914 | F27: pcs | G27: =E27+I27-I28 -> 3914 | H27: 入库 | I27: =SUM(J27:AO27) -> 0
H28: 出库 | I28: =SUM(J28:AO28) -> 0
A29: 12 | B29: 307E型 | C29: M4*0.7-L7-M6.5*0.8-OD9.0 | D29: SUS303 | E29: 2 | F29: pcs | G29: =E29+I29-I30 -> 2 | H29: 入库 | I29: =SUM(J29:AO29) -> 0
H30: 出库 | I30: =SUM(J30:AO30) -> 0
A31: 13 | B31: 307E型 | C31: M5*0.8-L8-M8*1.0-OD11.0 | D31: SUS303 | E31: 4793 | F31: pcs | G31: =E31+I31-I32 -> 4793 | H31: 入库 | I31: =SUM(J31:AO31) -> 0
H32: 出库 | I32: =SUM(J32:AO32) -> 0
A33: 14 | B33: 307E型 | C33: M6*1.0-L9.5-M10*1.25-OD13.0 | D33: SUS303 | E33: 14327 | F33: pcs | G33: =E33+I33-I34 -> 13627 | H33: 入库 | I33: =SUM(J33:AO33) -> 0
H34: 出库 | I34: =SUM(J34:AO34) -> 700 | P34: 200 | U34: 500
A35: 15 | B35: 307E型 | C35: M6*1.0-L10.5-M10*1.25-OD13.0 | D35: SUS303 | E35: 3283 | F35: pcs | G35: =E35+I35-I36 -> 3283 | H35: 入库 | I35: =SUM(J35:AO35) -> 0
H36: 出库 | I36: =SUM(J36:AO36) -> 0
A37: 16 | B37: 307E型 | C37: M8*1.25-L10.5-M12*1.5-OD15.0 | D37: SUS303 | E37: 465 | F37: pcs | G37: =E37+I37-I38 -> 465 | H37: 入库 | I37: =SUM(J37:AO37) -> 0
H38: 出库 | I38: =SUM(J38:AO38) -> 0
A39: 17 | B39: 307E型 | C39: M10*1.5-L11.5-M14*1.5-OD17.0 | D39: SUS303 | E39: 1876 | F39: pcs | G39: =E39+I39-I40 -> 1801 | H39: 入库 | I39: =SUM(J39:AO39) -> 0
H40: 出库 | I40: =SUM(J40:AO40) -> 75 | N40: 5 | AA40: 70
...

Sheet DIN7965型
A1: DIN7965型库存明细
A2: 日期 | B2: ='302槽型'!B2 -> 46023 | D2: 本月入库统计 | H2: 每日入库统计 | J2: =SUMIF($H:$H,#REF!,J:J) -> 0 | K2: =SUMIF($H:$H,#REF!,K:K) -> 0 | L2: =SUMIF($H:$H,#REF!,L:L) -> 0 | M2: =SUMIF($H:$H,#REF!,M:M) -> 0 | N2: =SUMIF($H:$H,#REF!,N:N) -> 0 | O2: =SUMIF($H:$H,#REF!,O:O) -> 0 | P2: =SUMIF($H:$H,#REF!,P:P) -> 0 | Q2: =SUMIF($H:$H,#REF!,Q:Q) -> 0 | R2: =SUMIF($H:$H,#REF!,R:R) -> 0 | S2: =SUMIF($H:$H,#REF!,S:S) -> 0 | T2: =SUMIF($H:$H,#REF!,T:T) -> 0 | U2: =SUMIF($H:$H,#REF!,U:U) -> 0 | V2: =SUMIF($H:$H,#REF!,V:V) -> 0 | W2: =SUMIF($H:$H,#REF!,W:W) -> 0 | X2: =SUMIF($H:$H,#REF!,X:X) -> 0 | Y2: =SUMIF($H:$H,#REF!,Y:Y) -> 0
D3: 本月出库统计 | H3: 每日出库统计 | J3: =SUMIF($H:$H,#REF!,J:J) -> 0 | K3: =SUMIF($H:$H,#REF!,K:K) -> 0 | L3: =SUMIF($H:$H,#REF!,L:L) -> 0 | M3: =SUMIF($H:$H,#REF!,M:M) -> 0 | N3: =SUMIF($H:$H,#REF!,N:N) -> 0 | O3: =SUMIF($H:$H,#REF!,O:O) -> 0 | P3: =SUMIF($H:$H,#REF!,P:P) -> 0 | Q3: =SUMIF($H:$H,#REF!,Q:Q) -> 0 | R3: =SUMIF($H:$H,#REF!,R:R) -> 0 | S3: =SUMIF($H:$H,#REF!,S:S) -> 0 | T3: =SUMIF($H:$H,#REF!,T:T) -> 0 | U3: =SUMIF($H:$H,#REF!,U:U) -> 0 | V3: =SUMIF($H:$H,#REF!,V:V) -> 0 | W3: =SUMIF($H:$H,#REF!,W:W) -> 0 | X3: =SUMIF($H:$H,#REF!,X:X) -> 0 | Y3: =SUMIF($H:$H,#REF!,Y:Y) -> 0
A4: 序号 | B4: 类别 | C4: 规格 | D4: 材质 | E4: 上月结存 | F4: 单位 | G4: 现库存 | H4: 入/出库 | I4: 汇总 | J4: ='302槽型'!J4 -> 46023 | K4: ='302槽型'!K4 -> 46024 | L4: ='302槽型'!L4 -> 46025 | M4: ='302槽型'!M4 -> 46026 | N4: ='302槽型'!N4 -> 46027 | O4: ='302槽型'!O4 -> 46028 | P4: ='302槽型'!P4 -> 46029 | Q4: ='302槽型'!Q4 -> 46030 | ... AN4: ='302槽型'!AN4 -> 46053
A5: 1 | B5: DIN7965 | C5: M3*0.5-L8-OD6.0 | D5: SUS303 | E5: 19615 | F5: PCS | G5: =E5+I5-I6 -> 19615 | H5: 入库 | I5: =SUM(J5:AO5) -> 0
H6: 出库 | I6: =SUM(J6:AO6) -> 0
A7: 2 | B7: DIN7965 | C7: M4*0.7-L10-OD8.0 | D7: SUS303 | E7: 343 | F7: PCS | G7: =E7+I7-I8 -> 343 | H7: 入库 | I7: =SUM(J7:AO7) -> 0
H8: 出库 | I8: =SUM(J8:AO8) -> 0
A9: 2 | B9: DIN7965-2 | C9: M4*0.7-L10-OD8.0*2.35 | D9: C3604 | E9: 775 | F9: PCS | G9: =E9+I9-I10 -> 775 | H9: 入库 | I9: =SUM(J9:AO9) -> 0
H10: 出库 | I10: =SUM(J10:AO10) -> 0
A11: 3 | B11: DIN7965 | C11: M5*0.8-L10-OD10.0 | D11: SUS303 | E11: 2930 | F11: PCS | G11: =E11+I11-I12 -> 2930 | H11: 入库 | I11: =SUM(J11:AO11) -> 0
H12: 出库 | I12: =SUM(J12:AO12) -> 0
A13: 3 | B13: DIN7965 | C13: M5*0.8-L12-OD10.0 | D13: 304材质 | E13: 0 | F13: PCS | G13: =E13+I13-I14 -> 0 | H13: 入库 | I13: =SUM(J13:AO13) -> 0
H14: 出库 | I14: =SUM(J14:AO14) -> 0
A15: 3 | B15: DIN7965 | C15: M5*0.8-L12-OD10.0 | D15: SUS303 | E15: 3 | F15: PCS | G15: =E15+I15-I16 -> 3 | H15: 入库 | I15: =SUM(J15:AO15) -> 0
H16: 出库 | I16: =SUM(J16:AO16) -> 0
A17: 4 | B17: DIN7965 | C17: M5*0.8-L15-OD10.0 | D17: SUS303 | E17: 532 | F17: PCS | G17: =E17+I17-I18 -> 532 | H17: 入库 | I17: =SUM(J17:AO17) -> 0
H18: 出库 | I18: =SUM(J18:AO18) -> 0
A19: 5 | B19: DIN7965 | C19: M6*1.0-L15-OD12.0 | D19: SUS303 | E19: 1018 | F19: PCS | G19: =E19+I19-I20 -> 8306 | H19: 入库 | I19: =SUM(J19:AO19) -> 15295 | K19: 4345 | L19: 2530 | O19: 970 | S19: 4595 | W19: 2855
H20: 出库 | I20: =SUM(J20:AO20) -> 8007 | K20: 5000 | O20: 3000 | AK20: 4 | AL20: 3
A21: 6 | B21: DIN7965 | C21: M6*1.0-L12-OD12.0 | D21: SUS303 | E21: 738 | F21: PCS | G21: =E21+I21-I22 -> 6170 | H21: 入库 | I21: =SUM(J21:AO21) -> 10435 | L21: 5440 | Q21: 2870 | S21: 2125
H22: 出库 | I22: =SUM(J22:AO22) -> 5003 | L22: 5000 | AL22: 3
A23: 7 | B23: DIN7965 | C23: M6*1.0-L18-OD12.0 | D23: SUS303 | E23: 710 | F23: PCS | G23: =E23+I23-I24 -> 710 | H23: 入库 | I23: =SUM(J23:AO23) -> 0
H24: 出库 | I24: =SUM(J24:AO24) -> 0
A25: 7 | B25: DIN7965-2 | C25: M6*1.0-L7-OD12.0 | D25: SUS303 | E25: 70 | F25: PCS | G25: =E25+I25-I26 -> 70 | H25: 入库 | I25: =SUM(J25:AO25) -> 0
H26: 出库 | I26: =SUM(J26:AO26) -> 0
A27: 7 | B27: DIN7965-2 | C27: M6*1.0-L8-OD12.0 | D27: SUS303 | E27: 210 | F27: PCS | G27: =E27+I27-I28 -> 210 | H27: 入库 | I27: =SUM(J27:AO27) -> 0
H28: 出库 | I28: =SUM(J28:AO28) -> 0
A29: 7 | B29: DIN7965-2 | C29: M6*1.0-L10-OD12.0 | D29: SUS303 | E29: 285 | F29: PCS | G29: =E29+I29-I30 -> 285 | H29: 入库 | I29: =SUM(J29:AO29) -> 0
H30: 出库 | I30: =SUM(J30:AO30) -> 0
A31: 8 | B31: DIN7965-2 | C31: M8*1.25-L9-OD16.0 | D31: SUS303 | E31: 15 | F31: PCS | G31: =E31+I31-I32 -> 15 | H31: 入库 | I31: =SUM(J31:AO31) -> 0
H32: 出库 | I32: =SUM(J32:AO32) -> 0
A33: 8 | B33: DIN7965-2 | C33: M10*1.5-L15-OD18.5 | D33: SUS303 | E33: 0 | F33: PCS | G33: =E33+I33-I34 -> 5 | H33: 入库 | I33: =SUM(J33:AO33) -> 55 | AK33: 55
H34: 出库 | I34: =SUM(J34:AO34) -> 50 | AK34: 50
A35: 8 | B35: DIN7965 | C35: M8*1.25-L15-OD16.0 | D35: SUS303 | E35: 1535 | F35: PCS | G35: =E35+I35-I36 -> 1535 | H35: 入库 | I35: =SUM(J35:AO35) -> 0
H36: 出库 | I36: =SUM(J36:AO36) -> 0
A37: 9 | B37: DIN7965 | C37: M8*1.25-L15-OD14.0 | D37: SUS303 | E37: 499 | F37: PCS | G37: =E37+I37-I38 -> 299 | H37: 入库 | I37: =SUM(J37:AO37) -> 0
H38: 出库 | I38: =SUM(J38:AO38) -> 200 | AC38: 200
A39: 10 | B39: DIN7965 | C39: M8*1.25-L18-OD16.0 | D39: SUS303 | E39: 1422 | F39: PCS | G39: =E39+I39-I40 -> 1422 | H39: 入库 | I39: =SUM(J39:AO39) -> 0
H40: 出库 | I40: =SUM(J40:AO40) -> 0
...

Sheet 303 薄壁型 
A1: 303薄壁型库存明细
A2: 日期 | B2: ='302槽型'!B2 -> 46023 | D2: 本月入库统计 | H2: 每日入库统计 | J2: =SUMIF($H:$H,#REF!,J:J) -> 0 | K2: =SUMIF($H:$H,#REF!,K:K) -> 0 | L2: =SUMIF($H:$H,#REF!,L:L) -> 0 | M2: =SUMIF($H:$H,#REF!,M:M) -> 0 | N2: =SUMIF($H:$H,#REF!,N:N) -> 0 | O2: =SUMIF($H:$H,#REF!,O:O) -> 0 | P2: =SUMIF($H:$H,#REF!,P:P) -> 0 | Q2: =SUMIF($H:$H,#REF!,Q:Q) -> 0 | R2: =SUMIF($H:$H,#REF!,R:R) -> 0 | S2: =SUMIF($H:$H,#REF!,S:S) -> 0 | T2: =SUMIF($H:$H,#REF!,T:T) -> 0 | U2: =SUMIF($H:$H,#REF!,U:U) -> 0 | V2: =SUMIF($H:$H,#REF!,V:V) -> 0 | W2: =SUMIF($H:$H,#REF!,W:W) -> 0 | X2: =SUMIF($H:$H,#REF!,X:X) -> 0 | Y2: =SUMIF($H:$H,#REF!,Y:Y) -> 0
D3: 本月出库统计 | H3: 每日出库统计 | J3: =SUMIF($H:$H,#REF!,J:J) -> 0 | K3: =SUMIF($H:$H,#REF!,K:K) -> 0 | L3: =SUMIF($H:$H,#REF!,L:L) -> 0 | M3: =SUMIF($H:$H,#REF!,M:M) -> 0 | N3: =SUMIF($H:$H,#REF!,N:N) -> 0 | O3: =SUMIF($H:$H,#REF!,O:O) -> 0 | P3: =SUMIF($H:$H,#REF!,P:P) -> 0 | Q3: =SUMIF($H:$H,#REF!,Q:Q) -> 0 | R3: =SUMIF($H:$H,#REF!,R:R) -> 0 | S3: =SUMIF($H:$H,#REF!,S:S) -> 0 | T3: =SUMIF($H:$H,#REF!,T:T) -> 0 | U3: =SUMIF($H:$H,#REF!,U:U) -> 0 | V3: =SUMIF($H:$H,#REF!,V:V) -> 0 | W3: =SUMIF($H:$H,#REF!,W:W) -> 0 | X3: =SUMIF($H:$H,#REF!,X:X) -> 0 | Y3: =SUMIF($H:$H,#REF!,Y:Y) -> 0
A4: 序号 | B4: 类别 | C4: 规格 | D4: 材质 | E4: 上月结存 | F4: 单位 | G4: 现库存 | H4: 入/出库 | I4: 汇总 | J4: ='302槽型'!J4 -> 46023 | K4: ='302槽型'!K4 -> 46024 | L4: ='302槽型'!L4 -> 46025 | M4: ='302槽型'!M4 -> 46026 | N4: ='302槽型'!N4 -> 46027 | O4: ='302槽型'!O4 -> 46028 | P4: ='302槽型'!P4 -> 46029 | Q4: ='302槽型'!Q4 -> 46030 | ... AN4: ='302槽型'!AN4 -> 46053
A5: 1 | B5: 303薄壁型 | C5: M5*0.8-L8-M7*0.8 | D5: SUS303 | E5: 6346 | F5: pcs | G5: =E5+I5-I6 -> 6316 | H5: 入库 | I5: =SUM(J5:AO5) -> 0
H6: 出库 | I6: =SUM(J6:AO6) -> 30 | AD6: 30
A7: 2 | B7: 303薄壁型 | C7: M6*1.0-L8-M8*1.0 | D7: SUS303 | E7: 5360 | F7: pcs | G7: =E7+I7-I8 -> 5360 | H7: 入库 | I7: =SUM(J7:AO7) -> 0
H8: 出库 | I8: =SUM(J8:AO8) -> 0
A9: 3 | B9: 303薄壁型 | C9: M6*1.0-L10-M8*1.0 | D9: SUS303 | E9: 52046 | F9: pcs | G9: =E9+I9-I10 -> 52016 | H9: 入库 | I9: =SUM(J9:AO9) -> 0
H10: 出库 | I10: =SUM(J10:AO10) -> 30 | AD10: 30
A11: 4 | B11: 303薄壁型 | C11: M8*1.25-L12-M10*1.25 | D11: SUS303 | E11: 11830 | F11: pcs | G11: =E11+I11-I12 -> 10805 | H11: 入库 | I11: =SUM(J11:AO11) -> 0
H12: 出库 | I12: =SUM(J12:AO12) -> 1025 | O12: 1000 | T12: 25
A13: 4 | B13: 303薄壁型 | C13: M8*1.25-L12-M10*1.25 | D13: 316材质 | E13: 44 | F13: pcs | G13: =E13+I13-I14 -> 4319 | H13: 入库 | I13: =SUM(J13:AO13) -> 6535 | AE13: 2260 | AK13: 4275
H14: 出库 | I14: =SUM(J14:AO14) -> 2260 | AF14: 2260
A15: 5 | B15: 303薄壁型 | C15: M10*1.0-L10-M12*1.0 | D15: SUS303 | E15: 80 | F15: pcs | G15: =E15+I15-I16 -> 80 | H15: 入库 | I15: =SUM(J15:AO15) -> 0
H16: 出库 | I16: =SUM(J16:AO16) -> 0
A17: 6 | B17: 303薄壁型 | C17: M10*1.25-L13-M12*1.25 | D17: SUS303 | E17: 90 | F17: pcs | G17: =E17+I17-I18 -> 70 | H17: 入库 | I17: =SUM(J17:AO17) -> 0
H18: 出库 | I18: =SUM(J18:AO18) -> 20 | O18: 20
A19: 7 | B19: 303薄壁型 | C19: M10*1.25-L15-M12*1.25 | D19: SUS303 | E19: 1630 | F19: pcs | G19: =E19+I19-I20 -> 1610 | H19: 入库 | I19: =SUM(J19:AO19) -> 0
H20: 出库 | I20: =SUM(J20:AO20) -> 20 | O20: 20
A21: 8 | B21: 303薄壁型 | C21: M10*1.5-L15-M12*1.5 | D21: SUS303 | E21: 916 | F21: pcs | G21: =E21+I21-I22 -> 916 | H21: 入库 | I21: =SUM(J21:AO21) -> 0
H22: 出库 | I22: =SUM(J22:AO22) -> 0
A23: 9 | B23: 303薄壁型 | C23: M12*1.5-L14-M14*1.5 | D23: SUS303 | E23: 28 | F23: pcs | G23: =E23+I23-I24 -> 28 | H23: 入库 | I23: =SUM(J23:AO23) -> 0
H24: 出库 | I24: =SUM(J24:AO24) -> 0
A25: 10 | B25: 303薄壁型 | C25: M12*1.5-L18-M14*1.5 | D25: SUS303 | E25: 498 | F25: pcs | G25: =E25+I25-I26 -> 498 | H25: 入库 | I25: =SUM(J25:AO25) -> 0
H26: 出库 | I26: =SUM(J26:AO26) -> 0
A27: 11 | B27: 303薄壁型 | C27: M12*1.75-L18-M14*1.75 | D27: SUS303 | E27: 2080 | F27: pcs | G27: =E27+I27-I28 -> 2070 | H27: 入库 | I27: =SUM(J27:AO27) -> 0
H28: 出库 | I28: =SUM(J28:AO28) -> 10 | AF28: 10
A29: 12 | B29: 303薄壁型 | C29: M5*0.8-L8-M7*0.8 | D29: 1215黄锌 | E29: 3670 | F29: pcs | G29: =E29+I29-I30 -> 3670 | H29: 入库 | I29: =SUM(J29:AO29) -> 0
H30: 出库 | I30: =SUM(J30:AO30) -> 0
A31: 13 | B31: 303薄壁型 | C31: M6*1.0-L10-M8*1.0 | D31: 1215黄锌 | E31: 2560 | F31: pcs | G31: =E31+I31-I32 -> 2560 | H31: 入库 | I31: =SUM(J31:AO31) -> 0
H32: 出库 | I32: =SUM(J32:AO32) -> 0
A33: 14 | B33: 303薄壁型 | C33: M8*1.25-L12-M10*1.25 | D33: 1215黄锌 | E33: 22292 | F33: pcs | G33: =E33+I33-I34 -> 22292 | H33: 入库 | I33: =SUM(J33:AO33) -> 0
H34: 出库 | I34: =SUM(J34:AO34) -> 0
A35: 15 | B35: 303薄壁型 | C35: M10*1.25-L15-M12*1.25 | D35: 1215黄锌 | E35: 3180 | F35: pcs | G35: =E35+I35-I36 -> 3180 | H35: 入库 | I35: =SUM(J35:AO35) -> 0
H36: 出库 | I36: =SUM(J36:AO36) -> 0
